Workbook
Name 工地阶段: OFFSET([1]名称定义!$J$4,,,COUNTA([1]名称定义!$J:$J)-1)
Name 工地状态: OFFSET([1]名称定义!$H$4,,,COUNTA([1]名称定义!$H:$H)-1)
Name 合同状态: OFFSET([1]名称定义!$F$4,,,COUNTA([1]名称定义!$F:$F)-1)
Name 节假日: OFFSET([1]名称定义!$C$21,,,COUNTA([1]名称定义!$C:$C)-1)
Name 楼盘区域: OFFSET([1]名称定义!$L$4,,,COUNTA([1]名称定义!$L:$L)-1)
Name 渠道: OFFSET([1]名称定义!$P$4,,,COUNTA([1]名称定义!$P:$P)-1)
Name 收款状态: OFFSET([1]名称定义!$N$4,,,COUNTA([1]名称定义!$N:$N)-1)

Sheet 封面（打印）
A2: 九里晴川17-1-302——室内基础装饰工程报价清单
A5: 编制日期： | B5: =TODAY() -> 45694

Sheet 说明（打印）
A1: 报 价 说 明
A2: 1、 | B2: 本报价以本公司的工程管理模式为标准，重庆市建筑装饰协会编制的《重庆市住宅装饰市场指导价格》为依据，结合重庆市的实际情况进行编制。
A3: 2、 | B3: 本预算项目及材质以施工图为依据，甲乙双方协调为准；当预算项目及材质与施工图相抵触时，以实际预算清单内的项目和方量为准；若甲方签订施工合同之日起，六个月内无法开工因材料或人工涨价，则按乙方最新执行的报价定额进行调整。
A4: 3、 | B4: 本公司不承认任何口头承诺；甲方要求增加项目必须同乙方施工负责人办理增补手续，乙方才能进行施工；本方案签定合同后，甲方要求减少本方案所含项目，必须征得乙方同意，并对乙方补偿减项金额的10%、同时管理费不变。
A5: 4、 | B5: 本预算不包含主材材料、采购、加工及安装如:玻璃、石材、扣板、木地板、门类、墙纸、质感涂料、成品楼梯、栏杆、扶手、厨柜、不锈钢、五金配件、家电、活动家具、装饰画、装饰物品、文件柜、装饰柜、工艺品、软装饰等；只负责安装如:墙地砖、马赛克、配电箱及开关、插座和面板、灯具、洁具等(本条款具体相关内容及报价详情以报价清单为准!).甲供墙、地砖系列报价根据实际购买规格做相应调整。预算中不含材料及主材由甲方选购提供。
A6: 5、 | B6: 甲方自购成品套装门并由厂家负责安装维护，如果安装时需要乙方对原始门洞做基层处理时费用另计。
A7: 6、 | B7: 甲方自购石材并由厂家负责安装维护，乙方不负责辅料及造型基层处理，如果安装时需要乙方对基层处理时费用另计。
A8: 7、 | B8: 若甲方采用恒温容积式热水器、智能设备及其它类似特殊设备时.乙方需增加水路回路和电路回路报价,此二项费用另计。
A9: 8、 | B9: 墙、顶面基层不平超过20mm，开裂缝隙较大，墙面抹灰层差（掉灰等），墙面刮白基层差等基层问题较严重的，如预算上未计算处理费用，进场时乙方施工经理提出，与客户协商处理方法，办理增项。如甲方自愿不处理问题基层，由甲方确认基层情况后乙方进场施工，由此产生的所有问题，不在乙方质保范围内，由甲方自行负责。
A10: 9、 | B10: 原清水墙裂纹和小部份空鼓，大面积贴布处理20元/㎡，细小缝6元/㎡。
A11: 10、 | B11: 申请装修许可证、物业管理处收取的物管费、保险费、装修押金、室外出渣费、电梯费及施工期间的水、电费用等均由甲方支付；如因乙方施工人员造成小区设施、设备损坏的由乙方赔偿。
A12: 11、 | B12: 签定施工合同进场后：10天内减少项目按折扣减，减相应管理费；10天后减少项目按折扣减且不减管理费；增加项目管理费相应增加；增加项目无折扣。
A13: 12、 | B13: 本预算不含木饰面及基层处理、不含木作施工、不含石材及石材基层处理、不含硬包基层处理，由其它专业报价施工。
... A17: 16、 | B17: 施工面积为外墙内线面积。（电梯面积不计算；车库面积计算一半；大露台面积计算一半，小露台面积全算；楼梯面积每层全算；生活阳台全算）
B18: 客户签认：
B19: 日 期： 年 月 日

Sheet 报价汇总表（打印）
A1: 昱辰室内设计装饰工程报价汇总表
A2: 甲方（业主）姓名：徐老师 联系方式： 使用面积：170 工程地点：昱湖壹号17-1-1502 编制日期： | D2: =TODAY() -> 45694
A3: 一、 | B3: 土建直接费（元） | D3: ='土建报价（打印）'!I38 -> 24898.655
A4: 二、 | B4: 基础直接费（元） | D4: ='基装报价（打印）'!I143 -> 162658.98
A5: 三、 | B5: 木基层直接费（元） | D5: ='木基层报价（打印）'!I33 -> 23830.394
A6: 四、 | B6: 工程直接费（元） | C6: 一+二+三 | D6: =SUM(D3:D5) -> 211388.03
A7: 五、 | B7: 工程综合管理费12﹪ | C7: 四*12% | D7: =D6*0.12 -> 25366.564
A8: 六、 | B8: 工程总造价（元） | C8: 四+五 | D8: =D6+D7 -> 236754.59
A9: 备注： 该报价不含小区物管收取的出渣费、电梯费、管理费、装修保证金等费用
A10: 设计师（签字） 设计部经理（签字） 客户（与合同名字一致）（签字）
D13: 96折 合同价 | E13: =D8*0.96 -> 227284.41
E15: =E13/170 -> 1336.9671
B16: 土建+基础费 | C16: ='土建报价（打印）'!I40+'基装报价（打印）'!I145 -> 210064.55
C17: =C16*0.96 -> 201661.97

Sheet 土建报价（打印）
A1: 昱辰室内设计装饰工程报价表
A2: 甲方（业主）姓名：徐老师 联系方式： 使用面积： 170 工程地点：昱湖壹号17-1-1502 编制日期： | I2: =TODAY() -> 45694 | K2: 内部特别说明（不打印）
A3: 序号 | B3: 项目名称： | C3: 单位 | D3: 数量 | E3: 材料费 | G3: 人 工 费 | I3: 合计 | J3: 装饰内容及材质
E4: 主 | F4: 辅 | G4: 木(泥) | H4: 漆
A5: 一、土建拆除
A6: 1、 | B6: 拆除非承重墙 | C6: m2 | D6: =(3.3+3.85+0.57+3.4+2.58+2.8+2.8+2)*2.85 -> 60.705 | G6: 30 | I6: =D6*(E6+F6+G6+H6) -> 1821.15 | J6: 1、拆除人工费。 2、不含门窗拆除。 3、不含构造柱拆除，构造柱需根据实际情况另计。 | K6: 大小门窗洞全扣，门窗由回收单位拆除。
A7: 2、 | B7: 拆除半墙及修补 | C7: m2 | D7: =1.28*2.85 -> 3.648 | F7: 40 | G7: 70 | I7: =D7*(E7+F7+G7+H7) -> 401.28 | J7: 1、拆除人工费。 2、不含门窗拆除。 3、不含构造柱拆除，构造柱需根据实际情况另计。 | K7: 大小门窗洞全扣，门窗由回收单位拆除。
A8: 3、 | B8: 拆除构造柱 （主卧、次卧1/2、书房 提高门洞过梁） | C8: 根 | D8: 4 | G8: 150 | I8: =D8*(E8+F8+G8+H8) -> 600 | J8: 1、拆除人工费。
A9: 4、 | B9: 拆除保温层 | C9: m2 | D9: =(8.8-2.5)*2.75 -> 17.325 | G9: 20 | I9: =D9*(E9+F9+G9+H9) -> 346.5 | J9: 1、拆除人工费。 2、墙面拆除部分不重复计算保温层拆除。 | K9: 生活阳台及景观阳台有保温层
A10: 5、 | B10: 拆除保温层后抹灰 | C10: m2 | D10: =(8.8-2.5)*2.75 -> 17.325 | F10: 20 | G10: 25 | I10: =D10*(E10+F10+G10+H10) -> 779.625 | J10: 人工费+辅料
A11: 6、 | B11: 拆除阳台地梁处铝板 （厨房阳台栏杆不拆，直接做滑窗） | C11: 项 | F11: 150 | I11: =D11*(E11+F11+G11+H11) -> 0 | J11: 人工费+辅料 | K11: 铝板拆除可门窗做
A12: 7、 | B12: 拆除阳台地梁处铝板 （客厅阳台栏杆拆除，做大玻璃窗） | C12: m | F12: 60 | I12: =D12*(E12+F12+G12+H12) -> 0 | J12: 人工费+辅料
A13: 8、 | B13: 拆除飘窗及修补（红砖） | C13: m | D13: =6.1+4.1+6.7 -> 16.9 | F13: 100 | G13: 200 | I13: =D13*(E13+F13+G13+H13) -> 5070 | J13: 1、拆除人工费。 2、不含构造柱拆除。 3、混凝土结构另计增加150/米。
A14: 9、 | B14: 拆除飘窗及修补（混凝土） | C14: m | F14: 100 | G14: 350 | I14: =D14*(E14+F14+G14+H14) -> 0 | J14: 1、拆除人工费。 2、不含构造柱拆除。
A15: 10、 | B15: 拆除飘窗后墙地面防水 | C15: m2 | D15: =(2.4+2.97+3.51)+(4.6+5.3+5.7)*0.58 -> 17.928 | F15: 25 | G15: 45 | I15: =D15*(E15+F15+G15+H15) -> 1254.96 | J15: 1、法国“圣戈班伟伯”防水（刷二遍）；2、清洁并润湿原墙；3、向地面延伸100-200㎜，阴角饱满。
A16: 11、 | B16: 原有墙\柱\梁倒圆角制作（R50mm以内） | C16: m | E16: 20 | I16: =D16*(E16+F16+G16+H16) -> 0 | J16: 1、石匠踢打 2、R型阳角条漆工施工
A17: 12、 | B17: 原有墙\柱\梁倒圆角制作（大于R50mm，小于R200mm） （客厅） | C17: m | D17: 2.85 | E17: 20 | G17: 60 | I17: =D17*(E17+F17+G17+H17) -> 228 | J17: 1、石匠踢打 2、泥工搓沙
A18: 13、 | B18: 原有墙\柱\梁倒圆角制作（大于R200mm） | C18: m | E18: 40 | G18: 100 | I18: =D18*(E18+F18+G18+H18) -> 0 | J18: 1、红砖砌体 2、泥工搓沙
A19: 二、土建新建
A20: 1、 | B20: 新砌100厚轻质砖墙 | C20: m2 | E20: 70 | F20: 25 | G20: 50 | I20: =D20*(E20+F20+G20+H20) -> 0 | J20: 1、大面积加气混凝土砌体、局部红砖、水泥砂浆。使用于除地下室以外的区域；2、尺寸正确，表面平整，立面垂直。 | K20: 家装不允许使用轻质砖墙（加气砖），均计算为红砖。轻质砖仅起隔墙作用，红砖则有隔音隔热及承重。
A21: 2、 | B21: 新砌200厚轻质砖墙 | C21: m2 | E21: 160 | F21: 30 | G21: 40 | I21: =D21*(E21+F21+G21+H21) -> 0 | J21: 1、大面积加气混凝土砌体、局部红砖、水泥砂浆。使用于除地下室以外的区域；2、尺寸正确，表面平整，立面垂直。 | K21: 家装不允许使用轻质砖墙（加气砖），均计算为红砖。轻质砖仅起隔墙作用，红砖则有隔音隔热及承重。
A22: 3、 | B22: 新砌砖墙（墙厚≤120mm） | C22: m2 | D22: =(1.82+0.57+2.9+0.6+0.4+1.25+2.27+2.5+0.55+0.74+0.2)*2.85 -> 39.33 | E22: 90 | F22: 15 | G22: 60 | I22: =D22*(E22+F22+G22+H22) -> 6489.45 | J22: 1、红砖、水泥砂浆。只使用于地下室；2、尺寸正确，表面平整，立面垂直。 | K22: 不加过梁的大小门窗洞全扣； 加过梁＜2㎡门窗洞不扣；加过梁≥2㎡门窗洞扣一半
A23: 4、 | B23: 新砌砖墙（120＜墙厚≤240mm） | C23: m2 | D23: =1.18*2.85-2 -> 1.363 | E23: 170 | F23: 20 | G23: 70 | I23: =D23*(E23+F23+G23+H23) -> 354.38 | J23: 1、红砖、水泥砂浆。只使用于地下室；2、尺寸正确，表面平整，立面垂直。 | K23: 不加过梁的大小门窗洞全扣； 加过梁＜2㎡门窗洞不扣；加过梁≥2㎡门窗洞扣一半
A24: 5、 | B24: 单面抹灰、搓沙（按实计算） | C24: m2 | E24: 20 | G24: 15 | I24: =D24*(E24+F24+G24+H24) -> 0 | J24: 1、水泥砂浆找平，综合价，厚度在30mm内不作调整；2、尺寸正确，表面平整，立面垂直。
A25: 6、 | B25: 双面抹灰、搓沙（按实计算） | C25: m2 | D25: =D22+D23 -> 40.693 | E25: 40 | G25: 30 | I25: =D25*(E25+F25+G25+H25) -> 2848.51 | J25: 1、水泥砂浆找平，综合价，厚度在30mm内不作调整；2、尺寸正确，表面平整，立面垂直。
A26: 7、 | B26: 开门洞 | C26: 个 | G26: 150 | I26: =D26*(E26+F26+G26+H26) -> 0 | J26: 1、开门洞人工费。
A27: 8、 | B27: 1000mm以下宽门洞过梁 （主卧、主卫） | C27: 根 | D27: 2 | F27: 80 | G27: 110 | I27: =D27*(E27+F27+G27+H27) -> 380 | J27: 1、现浇过梁：钢筋+水泥+石子+砂+水；或预制过梁；2、梁端入墙100㎜以上。 2、大于1000mm计算为2根，以此类推。
A28: 9、 | B28: 新做浴缸基层（不含贴面） | C28: 个 | E28: 200 | F28: 50 | G28: 450 | I28: =D28*(E28+F28+G28+H28) -> 0 | J28: 1、红砖、水泥砂浆；2、尺寸正确，结构牢固，内侧抹灰收光。
A29: 10、 | B29: 烟道保护 | C29: m2 | D29: 1 | E29: 100 | F29: 15 | G29: 100 | I29: =D29*(E29+F29+G29+H29) -> 215 | J29: 红砖、水泥砂浆；（按展开面积计算。） | K29: 必须单独计算，不能直接算进新建墙内。
A30: 11、 | B30: 包落水管（按实际算） (厨房、次卫） | C30: 根 | D30: 2 | E30: 60 | F30: 15 | G30: 150 | I30: =D30*(E30+F30+G30+H30) -> 450 | J30: 1、红砖、水泥砂浆。 2、含阻力片及隔音棉1公分厚度。 | K30: 必须单独计算，不能直接算进新建墙内。 一根管子算一根，双管算2根。
A31: 12、 | B31: 电视墙加固 | C31: 项 | D31: 1 | E31: 100 | F31: 10 | G31: 80 | I31: =D31*(E31+F31+G31+H31) -> 190 | J31: 1、osb板或红砖+水泥、河砂；2、加固面积不得小于电视面积。
A32: 13、 | B32: 入墙马桶 | C32: 个 | F32: 100 | G32: 200 | I32: =D32*(E32+F32+G32+H32) -> 0 | J32: 暗藏水箱预埋（不含后期本体安装）。
A33: 14、 | B33: 入墙预埋龙头 （主次卫洗潄台） | C33: 个 | D33: 2 | F33: 50 | G33: 50 | I33: =D33*(E33+F33+G33+H33) -> 200 | J33: 开槽预埋件安装（不含后期本体安装）。
A34: 15、 | B34: 原门洞修补 | C34: 个 | E34: 50 | F34: 5 | G34: 80 | I34: =D34*(E34+F34+G34+H34) -> 0 | J34: 红砖、水泥砂浆或木龙骨（或木工板）+石膏板
A35: 16、 | B35: 厨房和卫生间地面返水梁高度200mm（宽度≤120mm） | C35: m | D35: =1.53+2.27+2.5+0.55+0.74 -> 7.59 | E35: 80 | F35: 20 | G35: 120 | I35: =D35*(E35+F35+G35+H35) -> 1669.8 | J35: 1、现浇120mm梁：钢筋+水泥+石子+砂+水； | K35: 止水梁使用425水泥
A36: 17、 | B36: 厨房和卫生间地面返水梁高度200mm（120≤宽度≤240mm） | C36: m | E36: 100 | F36: 20 | G36: 160 | I36: =D36*(E36+F36+G36+H36) -> 0 | J36: 1、现浇240mm梁：钢筋+水泥+石子+砂+水； | K36: 止水梁使用425水泥
A37: 18、 | B37: 厨房、卫生间、洗衣房、设备间、生活阳台线槽抹灰及防水处理 | C37: 个 | D37: 4 | E37: 100 | F37: 50 | G37: 250 | I37: =D37*(E37+F37+G37+H37) -> 1600 | J37: 1、线槽内刷防水 | K37: 厨房，卫生间，洗衣房、设备间
A38: （一）、工程直接费 | C38: 元 | I38: =SUM(I6:I37) -> 24898.655
A39: （二）、工程综合管理费=（一）*12﹪ | C39: 元 | I39: =I38*0.12 -> 2987.8386 | J39: 1、签定施工合同进场后：10天内减少项目 减少管理费、10天后减少项目不减管理费；2、增加项目管理费相应增加
A40: （三）、工程总造价=（一）+（二） | C40: 元 | I40: =I38+I39 -> 27886.494
...

Sheet 基装报价（打印）
A1: 昱辰室内设计装饰工程报价表
A2: 甲方（业主）姓名：徐老师 联系方式： 使用面积：170 工程地点： 编制日期： | I2: =TODAY() -> 45694
A3: 序号 | B3: 项目名称：昱湖壹号17-1-1502 | C3: 单位 | D3: 数量 | E3: 材料费 | G3: 人 工 费 | I3: 合计 | J3: 装饰内容及材质
E4: 主 | F4: 辅 | G4: 木(泥) | H4: 漆
A5: 一、客餐厅+厨房
A6: 1、 | B6: 天棚龙骨吊顶 (肯努森50系列） | C6: m2 | D6: =83.14-2.65-3.23-1.97-'木基层报价（打印）'!D9 -> 67.14 | E6: 42 | F6: 7.5 | G6: 33 | I6: =D6*(E6+F6+G6+H6) -> 5539.05 | J6: 大面积平顶“肯努森50系列”轻钢龙骨：1、主龙骨(0.8mm厚)间距800mm以内、副龙骨(0.5mm厚)间距300mm、沿边龙骨，Φ8mm国标吊筋固定；2、造型：大面平面部分轻钢龙骨，立面造型部分松木刨光木龙骨+欧松板（加拿大进口兔宝宝），木质刷防火涂料。3、根据设计大样图及现场实际情况调整欧松板厚度。 | K6: 不扣除梁面积
A7: 2、 | B7: 天棚封面(可耐福醛净单层） | C7: m2 | D7: =D6+28*0.35 -> 76.94 | E7: 40 | F7: 4.5 | G7: 37 | I7: =D7*(E7+F7+G7+H7) -> 6270.61 | J7: 1、可耐福（醛净系列）家装专用石膏板(9.5mm厚)、春雨镀锌自攻钉固定,螺丝间距150mm；2、石膏板拼接留V型缝。3、饰面另计。4、边吊转角做“L”型处理
A8: 3、 | B8: 天棚基层找平 | C8: m2 | D8: =D6+28*0.35 -> 76.94 | E8: 13 | F8: 6.5 | H8: 30 | I8: =D8*(E8+F8+G8+H8) -> 3808.53 | J8: 1、首先顶面用环保“圣戈班”石膏满找平；2、顶面基层批刮环保“圣戈班”面层找平腻子2-3遍，打磨平整。不含其他基层处理及涂料费用; 3、网格带或牛皮纸贴缝处理；4、阴阳角条；5、墙、顶面基层误差超过20㎜费用另计。
A9: 4、 | B9: 天棚木作叠级直线造型（无灯带、单级高度350mm内） | C9: m | D9: 23.18 | E9: 18 | F9: 3 | G9: 14 | I9: =D9*(E9+F9+G9+H9) -> 811.3 | J9: “肯努森”轻钢龙骨+可耐福（醛净系列）家装专用石膏板(9.5mm厚)，按单级延长米计算（单级高度350mm以上：按展开面积计费）
A10: 5、 | B10: 天棚木作叠级直线造型（有灯带、单级高度350mm内） | C10: m | D10: =4.9+4.6+(2.47+2.58)*2 -> 19.6 | E10: 18 | F10: 3 | G10: 28 | I10: =D10*(E10+F10+G10+H10) -> 960.4 | J10: “肯努森”轻钢龙骨+可耐福（醛净系列）家装专用石膏板(9.5mm厚)，按单级延长米计算（单级高度350mm以上： 按展开面积+有灯带叠级计费 ）
A11: 6、 | B11: 天棚木作叠级弧线(无灯带)造型 | C11: m | D11: 0.43 | E11: 38 | F11: 5 | G11: 35 | I11: =D11*(E11+F11+G11+H11) -> 33.54 | J11: 1、12mmOSB欧松板（加拿大进口兔宝宝）+五厘欧松板（加拿大进口兔宝宝）+可耐福（醛净系列）石膏板（单级高度350mm以内、含立面弧长400以内：超出按穹型吊顶+弧线叠级计费）按单级延长米计算+木质刷防火涂料 2、根据设计大样图及现场实际情况调整欧松板厚度。
A12: 7、 | B12: 天棚木作叠级弧线(有灯带)造型 | C12: m | D12: =5.24+0.94 -> 6.18 | E12: 38 | F12: 5 | G12: 55 | I12: =D12*(E12+F12+G12+H12) -> 605.64 | J12: 1、12mmOSB欧松板（加拿大进口兔宝宝）+五厘欧松板（加拿大进口兔宝宝）+可耐福（醛净系列）石膏板（单级高度350mm以内、含立面弧长400mm以内：超出按穹型吊顶+弧线叠级计费）按单级延长米计算+木质刷防火涂料 2、根据设计大样图及现场实际情况调整欧松板厚度。
A13: 8、 | B13: 天棚穹型边吊造型（弧长250mm以内） | C13: m | D13: 6.37 | E13: 70 | F13: 10 | G13: 80 | I13: =D13*(E13+F13+G13+H13) -> 1019.2 | J13: 1、松木刨光木龙骨+12mmOSB欧松板（加拿大进口兔宝宝）+可耐福（醛净系列）封面+“肯努森50系列”轻钢龙骨+木质刷防火涂料；2、膨胀螺栓，Φ8mm国标吊筋固定。3、根据设计大样图及现场实际情况调整欧松板厚度。 | K13: 立面带弧形的称为穹形，平面带弧形的称为弧形
A14: 9、 | B14: 天棚穹型吊顶(拱形顶，弧长≥250mm) （按投影面积计算） | C14: m2 | D14: =3.74*0.3 -> 1.122 | E14: 220 | F14: 50 | G14: 450 | I14: =D14*(E14+F14+G14+H14) -> 807.84 | J14: 1、松木刨光木龙骨+12mmOSB欧松板（加拿大进口兔宝宝）+可耐福（醛净系列）封面+“肯努森50系列”轻钢龙骨+木质刷防火涂料；2、膨胀螺栓，Φ8mm国标吊筋固定。3、根据设计大样图及现场实际情况调整欧松板厚度。 | K14: 立面带弧形的称为穹形，平面带弧形的称为弧形
A15: 10、 | B15: 窗帘盒（暗） | C15: m | D15: =3.5+1.8+4.61 -> 9.91 | E15: 30 | F15: 5 | G15: 45 | H15: 6 | I15: =D15*(E15+F15+G15+H15) -> 852.26 | J15: 1、12mmOSB欧松板（加拿大进口兔宝宝）+可耐福（醛净系列）石膏板(9.5mm厚)封面；高度200mm*宽度240mm以内 2、根据设计大样图及现场实际情况调整欧松板厚度。
A16: 11、 | B16: 厨卫地面防水处理 | C16: m2 | D16: 10.39 | E16: 65 | F16: 8 | G16: 22 | I16: =D16*(E16+F16+G16+H16) -> 987.05 | J16: 1、法国“圣戈班伟伯”防水（刷两遍）；2、墙面返高300㎜，阴角饱满；3、闭水试验72小时，无渗漏。闭水深度100mm，原墙面油性防水层清除。3、卫生间防水到吊顶高度、厨房1200mm。阴角做R型角处理，贴抗裂布加固，管根刷管不漏加固处理。
A17: 12、 | B17: 地面铺300≤规格＜600地砖（甲供杂砖） | C17: m2 | D17: 6.28 | F17: 25 | G17: 50 | I17: =D17*(E17+F17+G17+H17) -> 471 | J17: 1、32.5水泥沙浆铺贴地砖 +填缝剂 (甲方提供)，铺贴垫层厚度30mm-50mm,50mm以上需找平层加厚，加厚部分费用另计20元/㎡；2、实际用砖规格与预算不符以及实际施工方案与预算不符按实际办理增减项费用；3、平整无空鼓。
A18: 13、 | B18: 地面安装750≤规格≤1500地砖 （甲供） | C18: m2 | D18: =53.06-D17 -> 46.78 | F18: 25 | G18: 105 | I18: =D18*(E18+F18+G18+H18) -> 6081.4 | J18: 1、32.5水泥沙浆铺贴地砖 +填缝剂 (甲方提供)，铺贴垫层厚度30mm-50mm,50mm以上需找平层加厚，加厚部分费用另计20元/㎡；2、实际用砖规格与预算不符以及实际施工方案与预算不符按实际办理增减项费用；3、平整无空鼓。
A19: 14、 | B19: 墙面基层找平处理 | C19: m2 | D19: =(46.29-10.75)*2.5-8*2-2.45*1.32 -> 69.616 | E19: 10 | F19: 7 | H19: 35 | I19: =D19*(E19+F19+G19+H19) -> 3620.032 | J19: 1、批刮环保“圣戈班”面层找平腻子2-3遍，打磨平整。不含其它基层处理及涂料费用。铲除原墙面或纯毛坯房找平，价格另计。2、网格带或牛皮纸贴缝处理；3、阴阳直角角条；4、墙、顶面基层误差超过20㎜费用另计。 | K19: 小于2㎡不扣，≥2㎡扣一半
A20: 15、 | B20: 墙面满挂玻纤抗裂网 （柜体背后不挂） | C20: m2 | D20: =(46.29-10.75-1.3-4.4-1.23)*2.5-8*2-2.45*1.32 -> 52.291 | E20: 3 | F20: 5 | G20: 5 | I20: =D20*(E20+F20+G20+H20) -> 679.783 | J20: 1、水电线槽用白布处理完成后环保“圣戈班”石膏满挂玻纤抗裂网； | K20: 小于2㎡不扣，≥2㎡扣一半
A21: 16、 | B21: 厨卫墙面防水处理 （厨房）---1.2M | C21: m2 | D21: =10.75*1.2 -> 12.9 | E21: 65 | F21: 8 | G21: 25 | I21: =D21*(E21+F21+G21+H21) -> 1264.2 | J21: 1、法国“圣戈班伟伯”防水（刷二遍）；2、清洁并润湿原墙；3、向地面延伸100-200㎜，阴角饱满。 | K21: 不碰角大小门窗洞全扣； 碰角＜2㎡门窗洞不扣；碰角≥2㎡门窗洞扣一半
A22: 17、 | B22: 厨房和卫生间墙面满墙搓沙找平 | C22: m2 | D22: =10.75*2.5 -> 26.875 | E22: 0 | F22: 30 | G22: 35 | I22: =D22*(E22+F22+G22+H22) -> 1746.875 | J22: 1、原有墙面开发商防水全部铲除，涂刷界面剂，批刮抗裂砂浆；2、墙面32.5水泥砂浆满墙搓沙找平；3、找直找方； | K22: 不碰角大小门窗洞全扣； 碰角＜2㎡门窗洞不扣；碰角≥2㎡门窗洞扣一半
A23: 18、 | B23: 墙面贴300*600墙砖 （甲供杂砖） | C23: m2 | D23: =10.75*0.7 -> 7.525 | F23: 35 | G23: 45 | I23: =D23*(E23+F23+G23+H23) -> 602 | J23: 1、美国“雷帝”瓷砖胶(C1T）铺贴墙砖,排缝另加6元/平方米。2、不含原墙面处理，勾缝剂、主材等甲供。 3、按展开面积计量。
A24: 19、 | B24: 墙面贴750*1500墙砖 （甲供） | C24: m2 | D24: =D22-D23 -> 19.35 | F24: 35 | G24: 145 | I24: =D24*(E24+F24+G24+H24) -> 3483 | J24: 1、美国“雷帝”瓷砖胶(C2T）铺贴墙砖,排缝另加6元/平方米。2、不含原墙面处理，勾缝剂、主材等甲供。 3、按展开面积计量。
A25: 20、 | B25: 倒圆角 | C25: m | D25: =10.47+5.74+12.14+10.73 -> 39.08 | F25: 10 | G25: 10 | I25: =D25*(E25+F25+G25+H25) -> 781.6 | J25: 人工+辅材
A26: 二、次卧1（父母房）
A27: 1、 | B27: 天棚龙骨吊顶 (肯努森50系列） | C27: m2 | D27: 15.46 | E27: 42 | F27: 7.5 | G27: 33 | I27: =D27*(E27+F27+G27+H27) -> 1275.45 | J27: 大面积平顶“肯努森50系列”轻钢龙骨：1、主龙骨(0.8mm厚)间距800mm以内、副龙骨(0.5mm厚)间距300mm、沿边龙骨，Φ8mm国标吊筋固定；2、造型：大面平面部分轻钢龙骨，立面造型部分松木刨光木龙骨+欧松板（加拿大进口兔宝宝），木质刷防火涂料。3、根据设计大样图及现场实际情况调整欧松板厚度。 | K27: 不扣除梁面积
A28: 2、 | B28: 天棚封面(可耐福醛净单层） | C28: m2 | D28: =15.46+3*0.35 -> 16.51 | E28: 40 | F28: 4.5 | G28: 37 | I28: =D28*(E28+F28+G28+H28) -> 1345.565 | J28: 1、可耐福（醛净系列）家装专用石膏板(9.5mm厚)、春雨镀锌自攻钉固定,螺丝间距150mm；2、石膏板拼接留V型缝。3、饰面另计。4、边吊转角做“L”型处理
A29: 3、 | B29: 天棚木作叠级直线造型（有灯带、单级高度350mm内） | C29: m | D29: 3 | E29: 18 | F29: 3 | G29: 28 | I29: =D29*(E29+F29+G29+H29) -> 147 | J29: “肯努森”轻钢龙骨+可耐福（醛净系列）家装专用石膏板(9.5mm厚)，按单级延长米计算（单级高度350mm以上： 按展开面积+有灯带叠级计费 ）
A30: 4、 | B30: 天棚基层找平 | C30: m2 | D30: =D28 -> 16.51 | E30: 13 | F30: 6.5 | H30: 30 | I30: =D30*(E30+F30+G30+H30) -> 817.245 | J30: 1、首先顶面用环保“圣戈班”石膏满找平；2、顶面基层批刮环保“圣戈班”面层找平腻子2-3遍，打磨平整。不含其他基层处理及涂料费用; 3、网格带或牛皮纸贴缝处理；4、阴阳角条；5、墙、顶面基层误差超过20㎜费用另计。
A31: 5、 | B31: 窗帘盒（暗）有灯带总长 | C31: m | D31: 3 | E31: 30 | F31: 5 | G31: 50 | H31: 7 | I31: =D31*(E31+F31+G31+H31) -> 276 | J31: 1、12mmOSB欧松板（加拿大进口兔宝宝））+可耐福（醛净系列）石膏板(9.5mm厚)封面；高度200mm*宽度240mm以内 2、根据设计大样图及现场实际情况调整欧松板厚度。
A32: 6、 | B32: 地面铺砖找平（木地板找平基层） | C32: m2 | D32: 15.46 | E32: 50 | F32: 25 | G32: 30 | I32: =D32*(E32+F32+G32+H32) -> 1623.3 | J32: 1、32.5水泥沙浆铺贴地砖 +普通耐磨哑光瓷砖，铺贴垫层厚度30mm-50mm，50mm以上需找平层加厚，加厚部分费用另计20元/㎡；2、实际用砖规格与预算不符以及实际施工方案与预算不符按实际办理增减项费用；3、平整无空鼓。
A33: 7、 | B33: 墙面基层找平处理 | C33: m2 | D33: =17.5*2.5-1.8*1.77-2 -> 38.564 | E33: 10 | F33: 7 | H33: 35 | I33: =D33*(E33+F33+G33+H33) -> 2005.328 | J33: 1、批刮环保“圣戈班”面层找平腻子2-3遍，打磨平整。不含其它基层处理及涂料费用。铲除原墙面或纯毛坯房找平，价格另计。2、网格带或牛皮纸贴缝处理；3、阴阳直角角条；4、墙、顶面基层误差超过20㎜费用另计。 | K33: 小于2㎡不扣，≥2㎡扣一半
A34: 8、 | B34: 墙面满挂玻纤抗裂网 （柜体背后不挂） | C34: m2 | D34: =(17.5-1.9)*2.5-1.8*1.77-2 -> 33.814 | E34: 3 | F34: 5 | G34: 5 | I34: =D34*(E34+F34+G34+H34) -> 439.582 | J34: 1、水电线槽用白布处理完成后环保“圣戈班”石膏满挂玻纤抗裂网； | K34: 小于2㎡不扣，≥2㎡扣一半
A35: 9、 | B35: 倒圆角 | C35: m | D35: 3 | F35: 10 | G35: 10 | I35: =D35*(E35+F35+G35+H35) -> 60 | J35: 人工+辅材
A36: 三、次卧2（儿童房）
A37: 1、 | B37: 天棚龙骨吊顶 (肯努森50系列） | C37: m2 | D37: =11.38-1.22 -> 10.16 | E37: 42 | F37: 7.5 | G37: 33 | I37: =D37*(E37+F37+G37+H37) -> 838.2 | J37: 大面积平顶“肯努森50系列”轻钢龙骨：1、主龙骨(0.8mm厚)间距800mm以内、副龙骨(0.5mm厚)间距300mm、沿边龙骨，Φ8mm国标吊筋固定；2、造型：大面平面部分轻钢龙骨，立面造型部分松木刨光木龙骨+欧松板（加拿大进口兔宝宝），木质刷防火涂料。3、根据设计大样图及现场实际情况调整欧松板厚度。 | K37: 不扣除梁面积
A38: 2、 | B38: 天棚封面(可耐福醛净单层） | C38: m2 | D38: =D37+5.35*0.35 -> 12.0325 | E38: 40 | F38: 4.5 | G38: 37 | I38: =D38*(E38+F38+G38+H38) -> 980.64875 | J38: 1、可耐福（醛净系列）家装专用石膏板(9.5mm厚)、春雨镀锌自攻钉固定,螺丝间距150mm；2、石膏板拼接留V型缝。3、饰面另计。4、边吊转角做“L”型处理
A39: 3、 | B39: 天棚木作叠级直线造型（无灯带、单级高度350mm内） | C39: m | D39: 5.35 | E39: 18 | F39: 3 | G39: 14 | I39: =D39*(E39+F39+G39+H39) -> 187.25 | J39: “肯努森”轻钢龙骨+可耐福（醛净系列）家装专用石膏板(9.5mm厚)，按单级延长米计算（单级高度350mm以上：按展开面积计费）
A40: 4、 | B40: 天棚木作叠级直线造型（有灯带、单级高度350mm内） | C40: m | D40: 4.78 | E40: 18 | F40: 3 | G40: 28 | I40: =D40*(E40+F40+G40+H40) -> 234.22 | J40: “肯努森”轻钢龙骨+可耐福（醛净系列）家装专用石膏板(9.5mm厚)，按单级延长米计算（单级高度350mm以上： 按展开面积+有灯带叠级计费 ）
...

Sheet 木基层报价（打印）
A1: 室内木基层工程报价清单
A2: 甲方（业主）姓名： 联系方式： 使用面积： 工程地点： 编制日期： | I2: =TODAY() -> 45694 | K2: 内部特别说明（不打印）
A3: 序号 | B3: 项目名称 | C3: 单位 | D3: 数量 | E3: 材料费 | G3: 人 工 费 | I3: 合计 | J3: 工艺做法及材料说明
E4: 主 | F4: 辅 | G4: 木(泥) | H4: 漆
A5: 一、木作基层工程
A6: 1、 | B6: 吊滑门基层加固 (厨房、书房、主卫） | C6: m | D6: =3.85+2.14+1.5 -> 7.49 | E6: 30 | F6: 10 | G6: 30 | I6: =D6*(E6+F6+G6+H6) -> 524.3 | J6: 15欧松板（加拿大进口兔宝宝）+龙骨基层；Φ8吊杆加固，纸面石膏板饰面
A7: 2、 | B7: 儿童玩耍区造型墙 墙面木作基层造型 | C7: m2 | D7: =1.35*2.85 -> 3.8475 | E7: 130 | F7: 10 | G7: 80 | I7: =D7*(E7+F7+G7+H7) -> 846.45 | J7: 1、12欧松板（加拿大进口兔宝宝）+龙骨基层 2、根据设计大样图及现场实际情况调整欧松板厚度。 | K7: 木饰面位置基层可以不计算，要求厂家施工或者做增项处理
A8: 3、 | B8: 倒圆角 | C8: m | F8: 10 | G8: 10 | I8: =D8*(E8+F8+G8+H8) -> 0 | J8: 人工+辅材
A9: 4、 | B9: 过道顶面木饰面基层 木作基层造型 | C9: m2 | D9: 8.15 | E9: 130 | F9: 10 | G9: 80 | I9: =D9*(E9+F9+G9+H9) -> 1793 | J9: 1、12欧松板（加拿大进口兔宝宝）+龙骨基层 2、根据设计大样图及现场实际情况调整欧松板厚度。 | K9: 木饰面位置基层可以不计算，要求厂家施工或者做增项处理
A10: 5、 | B10: 过道墙面木饰面基层 木作基层造型 | C10: m2 | D10: =4.96*2.47 -> 12.2512 | E10: 130 | F10: 10 | G10: 80 | I10: =D10*(E10+F10+G10+H10) -> 2695.264 | J10: 1、12欧松板（加拿大进口兔宝宝）+龙骨基层 2、根据设计大样图及现场实际情况调整欧松板厚度。 | K10: 木饰面位置基层可以不计算，要求厂家施工或者做增项处理
A11: 6、 | B11: 客厅电视背景墙 墙面木作基层造型 | C11: m2 | D11: =5.86*1.77 -> 10.3722 | E11: 130 | F11: 10 | G11: 80 | I11: =D11*(E11+F11+G11+H11) -> 2281.884 | J11: 1、12欧松板（加拿大进口兔宝宝）+龙骨基层 2、根据设计大样图及现场实际情况调整欧松板厚度。 | K11: 木饰面位置基层可以不计算，要求厂家施工或者做增项处理
A12: 7、 | B12: 客厅电视背景墙 封面(可耐福醛净单层） | C12: m2 | D12: =D11 -> 10.3722 | E12: 40 | F12: 4.5 | G12: 37 | I12: =D12*(E12+F12+G12+H12) -> 845.3343 | J12: 1、可耐福（醛净系列）家装专用石膏板(9.5mm厚)、春雨镀锌自攻钉固定,螺丝间距150mm；2、石膏板拼接留V型缝。3、饰面另计。4、边吊转角做“L”型处理
A13: 8、 | B13: 餐厅 墙面异形木作基层造型 | C13: m2 | D13: =0.73*2.15 -> 1.5695 | E13: =260-110 -> 150 | F13: 20 | G13: =240-80 -> 160 | I13: =D13*(E13+F13+G13+H13) -> 517.935 | J13: 1、12欧松板（加拿大进口兔宝宝）+龙骨基层 2、根据设计大样图及现场实际情况调整欧松板厚度。 | K13: 木饰面位置基层可以不计算，要求厂家施工或者做增项处理
A14: 9、 | B14: 餐厅 墙面异形石膏板封面(可耐福醛净单层） | C14: m2 | D14: =0.73*2.15 -> 1.5695 | E14: 60 | F14: 10 | G14: 50 | I14: =D14*(E14+F14+G14+H14) -> 188.34 | J14: 1、可耐福（醛净系列）家装专用石膏板(9.5mm厚)、春雨镀锌自攻钉固定,螺丝间距150mm；2、石膏板拼接留V型缝。3、饰面另计。4、边吊转角做“L”型处理
A15: 10、 | B15: 餐厅造型墙 墙面木作基层造型 | C15: m2 | D15: =2.8*2.15 -> 6.02 | E15: 130 | F15: 10 | G15: 80 | I15: =D15*(E15+F15+G15+H15) -> 1324.4 | J15: 1、12欧松板（加拿大进口兔宝宝）+龙骨基层 2、根据设计大样图及现场实际情况调整欧松板厚度。 | K15: 木饰面位置基层可以不计算，要求厂家施工或者做增项处理
A16: 11、 | B16: 餐厅造型墙 封面(可耐福醛净单层） | C16: m2 | D16: =D15 -> 6.02 | E16: 40 | F16: 4.5 | G16: 37 | I16: =D16*(E16+F16+G16+H16) -> 490.63 | J16: 1、可耐福（醛净系列）家装专用石膏板(9.5mm厚)、春雨镀锌自攻钉固定,螺丝间距150mm；2、石膏板拼接留V型缝。3、饰面另计。4、边吊转角做“L”型处理
A17: 12、 | B17: 主卧床头背景墙 墙面木作基层造型 | C17: m2 | D17: 3.65 | E17: 130 | F17: 10 | G17: 80 | I17: =D17*(E17+F17+G17+H17) -> 803 | J17: 1、12欧松板（加拿大进口兔宝宝）+龙骨基层 2、根据设计大样图及现场实际情况调整欧松板厚度。 | K17: 木饰面位置基层可以不计算，要求厂家施工或者做增项处理
A18: 13、 | B18: 父母房床头背景墙 墙面木作基层造型 | C18: m2 | D18: 3.7 | E18: 130 | F18: 10 | G18: 80 | I18: =D18*(E18+F18+G18+H18) -> 814 | J18: 1、12欧松板（加拿大进口兔宝宝）+龙骨基层 2、根据设计大样图及现场实际情况调整欧松板厚度。 | K18: 木饰面位置基层可以不计算，要求厂家施工或者做增项处理
A19: 14、 | B19: 暗踢脚墙体剔打，木基础，踢脚线安装 | C19: 米 | D19: =4.15+6.4+2.84+8+4.3+3+13.6-2.77+22.8-4.7+14.26-5.6-2 -> 64.28 | E19: 35 | F19: 20 | G19: 40 | I19: =D19*(E19+F19+G19+H19) -> 6106.6 | J19: 1、25-30mm踢脚线（含不锈钢或铝型材）。 2、30mm-50mm踢脚线需定制不锈钢不另外收费（含不锈钢）。 3、50mm以上踢脚线需定制不锈钢并另外收费20元/米（含不锈钢）。 4、定制颜色按20元/米增加费用。 | K19: 无踢脚线和内退踢脚线都需要计算,楼梯按步算，不按米算
A20: 15、 | B20: 隐框门木基层 | C20: 米 | D20: =3.1*3 -> 9.3 | E20: 65 | F20: 5 | G20: 45 | I20: =D20*(E20+F20+G20+H20) -> 1069.5 | J20: 1、12欧松板（加拿大进口兔宝宝）+龙骨基层 2、根据设计大样图及现场实际情况调整欧松板厚度。 3、不含木饰面位置木基层。 | K20: 按门洞周长计算
A21: 16、 | B21: 隐框门安装后收口处理 | C21: 米 | D21: =3.1*3 -> 9.3 | E21: 65 | F21: 5 | G21: 35 | I21: =D21*(E21+F21+G21+H21) -> 976.5 | J21: 1、12欧松板（加拿大进口兔宝宝）+龙骨基层+石膏板封面 2、根据设计大样图及现场实际情况调整欧松板厚度。 3、不含木饰面位置木基层。 | K21: 按门洞周长计算
A22: 17、 | B22: 极细边框木基层，定制不锈钢门套 | C22: 个 | E22: 45 | F22: 10 | G22: 60 | I22: =D22*(E22+F22+G22+H22) -> 0 | J22: 750-900MM宽门（不含不锈钢）
A23: 18、 | B23: 极细边框木基层，定制不锈钢门套 | C23: 个 | E23: 500 | F23: 400 | G23: 500 | I23: =D23*(E23+F23+G23+H23) -> 0 | J23: 750-900MM宽门（含不锈钢）
A24: 19、 | B24: 极细边框木基层，定制不锈钢门套 | C24: 米 | E24: 130 | F24: 30 | G24: 100 | I24: =D24*(E24+F24+G24+H24) -> 0 | J24: 门套宽度240mm以内（含不锈钢）
A25: 20、 | B25: 平板门，含把手，普通合页和门吸 | C25: 扇 | E25: 1800 | F25: 600 | G25: 300 | I25: =D25*(E25+F25+G25+H25) -> 0 | J25: 2000-2400MM高
A26: 21、 | B26: 中间铝蜂窝极窄边框门，含把手，普通合页和门吸 | C26: 扇 | E26: 2000 | F26: 700 | G26: 700 | I26: =D26*(E26+F26+G26+H26) -> 0 | J26: 2000-2400MM高
A27: 22、 | B27: 不锈钢门套木基层 | C27: 米 | E27: 65 | G27: 25 | I27: =D27*(E27+F27+G27+H27) -> 0 | J27: 1、12欧松板（加拿大进口兔宝宝）+龙骨基层 2、根据设计大样图及现场实际情况调整欧松板厚度。
A28: 23、 | B28: 滑门轨道加固 | C28: m | E28: 150 | G28: 200 | I28: =D28*(E28+F28+G28+H28) -> 0 | J28: 1、轨道钢架+木基层 | K28: 可列为非常规项目讲解
A29: 24、 | B29: 钢架基层造型 | C29: ㎡ | E29: 250 | G29: 200 | I29: =D29*(E29+F29+G29+H29) -> 0 | J29: 1、镀锌管，接头处涂刷防锈漆。 | K29: 可列为非常规项目讲解
A30: 25、 | B30: 晾衣架加固 | C30: 项 | E30: 200 | I30: =D30*(E30+F30+G30+H30) -> 0 | J30: 1、轨道钢架+木基层 | K30: 可列为非常规项目讲解
A31: （一）、工程直接费 | C31: 元 | I31: =SUM(I6:I30) -> 21277.137
A32: （二）、工程综合管理费=（一）*12﹪ | C32: 元 | I32: =I31*0.12 -> 2553.2565 | J32: 1、签定施工合同进场后：10天内减少项目 减少管理费、10天后减少项目不减管理费；2、增加项目管理费相应增加
A33: （三）、工程总造价=（一）+（二） | C33: 元 | I33: =I31+I32 -> 23830.394
A34: 备注： 该报价不含小区物管收取的出渣费、电梯费、管理费、装修保证金等费用
A35: 设计师（签字） 设计部经理（签字） 客户（与合同名字一致）（签字）

Sheet 基装报价（模板）
A1: 昱辰室内设计装饰工程报价表
A2: 甲方（业主）姓名： 联系方式： 使用面积： 工程地点： 编制日期： | I2: =TODAY() -> 45694 | K2: 内部特别说明（不打印）
A3: 序号 | B3: 项目名称： | C3: 单位 | D3: 数量 | E3: 材料费 | G3: 人 工 费 | I3: 合计 | J3: 装饰内容及材质
E4: 主 | F4: 辅 | G4: 木(泥) | H4: 漆
A5: 一、天棚工程
A6: A、 | B6: 天棚龙骨吊顶 (肯努森50系列） | C6: m2 | D6: 1 | E6: 42 | F6: 7.5 | G6: 33 | I6: =D6*(E6+F6+G6+H6) -> 82.5 | J6: 大面积平顶“肯努森50系列”轻钢龙骨：1、主龙骨(0.8mm厚)间距800mm以内、副龙骨(0.5mm厚)间距300mm、沿边龙骨，Φ8mm国标吊筋固定；2、造型：大面平面部分轻钢龙骨，立面造型部分松木刨光木龙骨+欧松板（加拿大进口兔宝宝），木质刷防火涂料。3、根据设计大样图及现场实际情况调整欧松板厚度。 | K6: 不扣除梁面积
A7: A、 | B7: 天棚龙骨吊顶 (肯努森60系列） | C7: m2 | D7: 1 | E7: 52 | F7: 7.5 | G7: 40 | I7: =D7*(E7+F7+G7+H7) -> 99.5 | J7: 大面积平顶“肯努森60系列”轻钢龙骨：1、主龙骨(1.0mm厚)间距800mm以内、副龙骨(0.6mm厚)间距300mm、沿边龙骨，Φ8mm国标吊筋固定；2、造型：大面平面部分轻钢龙骨，立面造型部分松木刨光木龙骨+欧松板（加拿大进口兔宝宝），木质刷防火涂料。3、根据设计大样图及现场实际情况调整欧松板厚度。
A8: A、 | B8: 天棚龙骨吊顶 (圣戈班60系列） | C8: m2 | D8: 1 | E8: 60 | F8: 7.5 | G8: 40 | I8: =D8*(E8+F8+G8+H8) -> 107.5 | J8: 大面积平顶“圣戈班60系列”轻钢龙骨：1、主龙骨(1.0mm厚)间距800mm以内、副龙骨(0.6mm厚)间距300mm、沿边龙骨，Φ8mm国标吊筋固定；2、造型：大面平面部分轻钢龙骨，立面造型部分松木刨光木龙骨+欧松板（加拿大进口兔宝宝），木质刷防火涂料。3、根据设计大样图及现场实际情况调整欧松板厚度。
A9: A、 | B9: 天棚封面(可耐福醛净单层） | C9: m2 | D9: 1 | E9: 40 | F9: 4.5 | G9: 37 | I9: =D9*(E9+F9+G9+H9) -> 81.5 | J9: 1、可耐福（醛净系列）家装专用石膏板(9.5mm厚)、春雨镀锌自攻钉固定,螺丝间距150mm；2、石膏板拼接留V型缝。3、饰面另计。4、边吊转角做“L”型处理
A10: A、 | B10: 天棚封面(可耐福醛净双层） | C10: m2 | D10: 1 | E10: 65 | F10: 5 | G10: 70 | I10: =D10*(E10+F10+G10+H10) -> 140 | J10: 1、双层可耐福（醛净系列）家装专用石膏板(9.5mm厚)、春雨镀锌自攻钉固定,螺丝间距150mm；2、石膏板拼接留V型缝。3、饰面另计。4、边吊转角做“L”型处理
A11: A、 | B11: 天棚封面(可耐福12mm福贝诺单层） | C11: m2 | D11: 1 | E11: 65 | F11: 5 | G11: 45 | I11: =D11*(E11+F11+G11+H11) -> 115 | J11: 1、可耐福（福贝诺系列）家装专用石膏板(12mm厚)、春雨镀锌自攻钉固定,螺丝间距150mm；2、石膏板拼接留V型缝。3、饰面另计。4、边吊转角做“L”型处理
A12: A、 | B12: 天棚封面(圣戈班B20醛净单层） | C12: m2 | D12: 1 | E12: 40 | F12: 4.5 | G12: 37 | I12: =D12*(E12+F12+G12+H12) -> 81.5 | J12: 1、单层圣戈班B20（醛净系列）家装专用石膏板(9.5mm厚)、春雨镀锌自攻钉固定,螺丝间距150mm；2、石膏板拼接留V型缝。3、饰面另计。4、边吊转角做“L”型处理
A13: A、 | B13: 天棚穹型吊顶(拱形顶，弧长≥250mm) （按投影面积计算） | C13: m2 | D13: 1 | E13: 220 | F13: 50 | G13: 450 | I13: =D13*(E13+F13+G13+H13) -> 720 | J13: 1、松木刨光木龙骨+12mmOSB欧松板（加拿大进口兔宝宝）+可耐福（醛净系列）封面+“肯努森50系列”轻钢龙骨+木质刷防火涂料；2、膨胀螺栓，Φ8mm国标吊筋固定。3、根据设计大样图及现场实际情况调整欧松板厚度。 | K13: 立面带弧形的称为穹形，平面带弧形的称为弧形
A14: A、 | B14: 天棚穹型边吊造型（弧长250mm以内） | C14: m | D14: 1 | E14: 70 | F14: 10 | G14: 80 | I14: =D14*(E14+F14+G14+H14) -> 160 | J14: 1、松木刨光木龙骨+12mmOSB欧松板（加拿大进口兔宝宝）+可耐福（醛净系列）封面+“肯努森50系列”轻钢龙骨+木质刷防火涂料；2、膨胀螺栓，Φ8mm国标吊筋固定。3、根据设计大样图及现场实际情况调整欧松板厚度。 | K14: 立面带弧形的称为穹形，平面带弧形的称为弧形
A15: A、 | B15: 天棚面板水缝吊平顶（斜顶：在此基础上增加45元/m2；不含叠级、缝深3mm） | C15: m2 | D15: 1 | E15: 130 | F15: 15 | G15: 70 | I15: =D15*(E15+F15+G15+H15) -> 215 | J15: 1、“肯努森50系列”轻钢龙骨+12mmOSB欧松板（加拿大进口兔宝宝）+水曲板(漆未计）；2、主龙骨(0.8mm厚)间距800-1000、副龙骨(0.5mm厚)间距400mm，Φ8mm国标吊筋固定。3、根据设计大样图及现场实际情况调整欧松板厚度。
A16: A、 | B16: 天棚面板水缝清水色漆/华润 | C16: m2 | D16: 1 | E16: 60 | F16: 4 | H16: 70 | I16: =D16*(E16+F16+G16+H16) -> 134 | J16: 1、华润(五合一) 透明聚氨酯(PU)漆 底漆两遍+面漆两遍（色漆增加50/m2)；2、漆面光滑，无流坠，无颗粒，色泽均匀，纹理清晰。
A17: A、 | B17: 天棚木作假梁基层造型 (延长米计算,周长不大于600mm，不含线条) | C17: m | D17: 1 | E17: 70 | F17: 15 | H17: 90 | I17: =D17*(E17+F17+G17+H17) -> 175 | J17: 1、12mmOSB欧松板（加拿大进口兔宝宝）+可耐福（醛净系列）封面 2、根据设计大样图及现场实际情况调整欧松板厚度。 | K17: 原梁木基层+石膏板的计算此项。
A18: A、 | B18: 木作基层假梁造型 (延长米计算,周长不大于600mm，不含线条)饰面甲供木饰面 | C18: m2 | D18: 1 | E18: 55 | F18: 15 | H18: 80 | I18: =D18*(E18+F18+G18+H18) -> 150 | J18: 1、12mmOSB欧松板（加拿大进口兔宝宝）+龙骨基层 2、根据设计大样图及现场实际情况调整欧松板厚度。 | K18: 原梁木基层+木饰面的计算此项
A19: A、 | B19: 天棚吊斜顶（按展开面积计算）（不含叠级） | C19: m2 | D19: 1 | E19: 80 | F19: 10 | G19: 90 | I19: =D19*(E19+F19+G19+H19) -> 180 | J19: 1、大面积平顶“肯努森50系列”轻钢龙骨:主龙骨(0.8mm厚)间距800mm以内，副龙骨(0.5mm厚)间距300mm、沿边龙骨；2、造型部分松木刨光木龙骨,间距300mm+可耐福（醛净系列）家装专用石膏板(9.5mm厚)+木质刷防火涂料。
A20: A、 | B20: 天棚石膏板水缝吊顶 | C20: m2 | D20: 1 | E20: 85 | F20: 15 | G20: 95 | H20: 15 | I20: =D20*(E20+F20+G20+H20) -> 210 | J20: 1、“肯努森”轻钢龙骨+可耐福（醛净系列）家装专用石膏板(9.5mm厚)封面+可耐福（醛净系列）家装专用石膏板(9.5mm厚)开条拼缝；2、主龙骨(0.8mm厚)间距800mm以内、副龙骨(0.5mm厚)间距300mm、沿边龙骨，Φ8mm国标吊筋固定。
A21: A、 | B21: 天棚石膏板水缝吊斜顶 | C21: m2 | D21: 1 | E21: 95 | F21: 15 | G21: 125 | H21: 30 | I21: =D21*(E21+F21+G21+H21) -> 265 | J21: 1、“肯努森”轻钢龙骨+可耐福（醛净系列）家装专用石膏板(9.5mm厚)封面+可耐福（醛净系列）家装专用石膏板(9.5mm厚)开条拼缝；2、主龙骨(0.8mm厚)间距800mm以内、副龙骨(0.5mm厚)间距300mm、沿边龙骨，Φ8mm国标吊筋固定。
A22: A、 | B22: 天棚木作叠级直线造型（无灯带、单级高度350mm内） | C22: m | D22: 1 | E22: 18 | F22: 3 | G22: 14 | I22: =D22*(E22+F22+G22+H22) -> 35 | J22: “肯努森”轻钢龙骨+可耐福（醛净系列）家装专用石膏板(9.5mm厚)，按单级延长米计算（单级高度350mm以上：按展开面积计费）
A23: A、 | B23: 天棚木作叠级直线造型（有灯带、单级高度350mm内） | C23: m | D23: 1 | E23: 18 | F23: 3 | G23: 28 | I23: =D23*(E23+F23+G23+H23) -> 49 | J23: “肯努森”轻钢龙骨+可耐福（醛净系列）家装专用石膏板(9.5mm厚)，按单级延长米计算（单级高度350mm以上： 按展开面积+有灯带叠级计费 ）
A24: A、 | B24: 天棚木作叠级弧线(无灯带)造型 | C24: m | D24: 1 | E24: 38 | F24: 5 | G24: 35 | I24: =D24*(E24+F24+G24+H24) -> 78 | J24: 1、12mmOSB欧松板（加拿大进口兔宝宝）+五厘欧松板（加拿大进口兔宝宝）+可耐福（醛净系列）石膏板（单级高度350mm以内、含立面弧长400以内：超出按穹型吊顶+弧线叠级计费）按单级延长米计算+木质刷防火涂料 2、根据设计大样图及现场实际情况调整欧松板厚度。
A25: A、 | B25: 天棚木作叠级弧线(有灯带)造型 | C25: m | D25: 1 | E25: 38 | F25: 5 | G25: 55 | I25: =D25*(E25+F25+G25+H25) -> 98 | J25: 1、12mmOSB欧松板（加拿大进口兔宝宝）+五厘欧松板（加拿大进口兔宝宝）+可耐福（醛净系列）石膏板（单级高度350mm以内、含立面弧长400mm以内：超出按穹型吊顶+弧线叠级计费）按单级延长米计算+木质刷防火涂料 2、根据设计大样图及现场实际情况调整欧松板厚度。
A26: A、 | B26: 石膏板吊顶弧形阳角 | C26: m | D26: 1 | E26: 10 | G26: 10 | I26: =D26*(E26+F26+G26+H26) -> 20 | J26: 1、12mmOSB欧松板（加拿大进口兔宝宝）+五厘欧松板（加拿大进口兔宝宝）+可耐福（醛净系列）石膏板（单级高度350mm以内、含立面弧长400mm以内：超出按穹型吊顶+弧线叠级计费）按单级延长米计算+木质刷防火涂料 2、根据设计大样图及现场实际情况调整欧松板厚度。
A27: A、 | B27: 窗帘盒（暗） | C27: m | D27: 1 | E27: 30 | F27: 5 | G27: 45 | H27: 6 | I27: =D27*(E27+F27+G27+H27) -> 86 | J27: 1、12mmOSB欧松板（加拿大进口兔宝宝）+可耐福（醛净系列）石膏板(9.5mm厚)封面；高度200mm*宽度240mm以内 2、根据设计大样图及现场实际情况调整欧松板厚度。
A28: A、 | B28: 窗帘盒（暗）有灯带总长 | C28: m | D28: 1 | E28: 30 | F28: 5 | G28: 50 | H28: 7 | I28: =D28*(E28+F28+G28+H28) -> 92 | J28: 1、12mmOSB欧松板（加拿大进口兔宝宝））+可耐福（醛净系列）石膏板(9.5mm厚)封面；高度200mm*宽度240mm以内 2、根据设计大样图及现场实际情况调整欧松板厚度。
A29: A、 | B29: 厨卫可耐福耐潮石膏板吊顶(单层石膏板） | C29: m2 | D29: 1 | E29: 85 | F29: 10 | G29: 85 | I29: =D29*(E29+F29+G29+H29) -> 180 | J29: 1、平顶“肯努森50系列”轻钢龙骨+可耐福耐潮石膏板；2、主龙骨(0.8mm厚)间距800mm以内、副龙骨(0.5mm厚)间距300mm、沿边龙骨，Φ8mm国标吊筋固定。螺丝间距150mm。
A30: A、 | B30: 可耐福耐潮石膏板吊顶(双层石膏板） | C30: m2 | D30: 1 | E30: 110 | F30: 10 | G30: 118 | I30: =D30*(E30+F30+G30+H30) -> 238 | J30: 1、平顶“肯努森50系列”轻钢龙骨+可耐福耐潮石膏板(不足2.8m2以2.8m2计算）；2、主龙骨(0.8mm厚)间距800mm以内、副龙骨(0.5mm厚)间距300、沿边龙骨，Φ8mm国标吊筋固定，螺丝间距150mm。
A31: A、 | B31: 石膏线刷乳胶漆（综合价，不含石膏线） | C31: m | D31: 1 | E31: 2.5 | F31: 1 | H31: 5 | I31: =D31*(E31+F31+G31+H31) -> 8.5 | J31: 石膏线修补、打磨+PPG大师漆。 | K31: 乳胶漆我方单位施工的有石膏线的才计算此项
A32: A、 | B32: 天棚基层找平 | C32: m2 | D32: 1 | E32: 13 | F32: 6.5 | H32: 30 | I32: =D32*(E32+F32+G32+H32) -> 49.5 | J32: 1、首先顶面用环保“圣戈班”石膏满找平；2、顶面基层批刮环保“圣戈班”面层找平腻子2-3遍，打磨平整。不含其他基层处理及涂料费用; 3、网格带或牛皮纸贴缝处理；4、阴阳角条；5、墙、顶面基层误差超过20㎜费用另计。
A33: A、 | B33: 天棚乳胶漆 | C33: m2 | D33: 1 | E33: 10 | F33: 1 | H33: 5 | I33: =D33*(E33+F33+G33+H33) -> 16 | J33: 1、PPG大师漆；2、大面滚涂局部刷涂工艺，底漆一遍，面漆两遍；底漆面漆合二为一的序列参照施工说明。（喷漆工艺另计5元/M2）
A34: A、 | B34: 天棚基层找平 （厨房、卫生间、生活阳台专用） | C34: m2 | D34: 1 | E34: 13 | F34: 6.5 | H34: 32 | I34: =D34*(E34+F34+G34+H34) -> 51.5 | J34: 1、首先顶面用环保“圣戈班”石膏满找平；2、顶面基层批刮环保“圣戈班”防潮找平腻子2-3遍，打磨平整。不含其他基层处理及涂料费用; 3、网格带或牛皮纸贴缝处理；4、阴阳角条；5、墙、顶面基层误差超过20㎜费用另计。
A35: A、 | B35: 天棚乳胶漆防水漆（厨房、卫生间、生活阳台专用） | C35: m2 | D35: 1 | E35: 15 | F35: 1 | H35: 5 | I35: =D35*(E35+F35+G35+H35) -> 21 | J35: 1、PPG大师漆外墙漆；2、大面滚涂局部刷涂工艺，底漆一遍，面漆两遍；底漆、面漆合二为一的序列参照施工说明。（喷漆工艺另计3元/M2）
A36: A、 | B36: 卡式灯槽 | C36: m | D36: 1 | E36: 30 | H36: 35 | I36: =D36*(E36+F36+G36+H36) -> 65 | J36: 1、12mmOSB欧松板（加拿大进口兔宝宝）+纸面石膏板(9.5mm厚) 2、根据设计大样图及现场实际情况调整欧松板厚度。 | K36: 线性灯、轨道灯、磁吸灯
A37: A、 | B37: 弧形楼梯底部吊顶 | C37: m2 | D37: 1 | E37: 110 | F37: 10 | H37: 150 | I37: =D37*(E37+F37+G37+H37) -> 270 | J37: 轻钢龙骨：1、主龙骨(0.8mm厚)间距800mm以内、副龙骨(0.5mm厚)间距300mm、沿边龙骨，Φ8mm国标吊筋固定；2、造型：大面平面部分轻钢龙骨，立面造型部分松木刨光木龙骨+欧松板（加拿大进口兔宝宝），木质刷防火涂料。3、根据设计大样图及现场实际情况调整欧松板厚度。
A38: 二、地面工程 （备注: 地砖斜贴 加5元/M2 、贴加工砖(不加工费) 加5元/M2 贴卡缝砖加5元/M2 拼花费用另计）
A39: A、 | B39: 地面铺100＜规格≤200地砖 （甲供）（含斜贴和卡缝） | C39: m2 | D39: 1 | F39: 25 | G39: 150 | I39: =D39*(E39+F39+G39+H39) -> 175 | J39: 1、32.5水泥沙浆铺贴地砖 +填缝剂 (甲方提供)，铺贴垫层厚度30mm-50mm,50mm以上需找平层加厚，加厚部分费用另计20元/㎡；2、实际用砖规格与预算不符以及实际施工方案与预算不符按实际办理增减项费用；3、平整无空鼓。
A40: A、 | B40: 地面铺300≤规格＜600地砖（甲供） | C40: m2 | D40: 1 | F40: 25 | G40: 50 | I40: =D40*(E40+F40+G40+H40) -> 75 | J40: 1、32.5水泥沙浆铺贴地砖 +填缝剂 (甲方提供)，铺贴垫层厚度30mm-50mm,50mm以上需找平层加厚，加厚部分费用另计20元/㎡；2、实际用砖规格与预算不符以及实际施工方案与预算不符按实际办理增减项费用；3、平整无空鼓。
...

Sheet 土建报价（模板）
A1: 昱辰室内设计装饰工程报价表
A2: 甲方（业主）姓名： 联系方式： 使用面积： 工程地点： 编制日期： | I2: =TODAY() -> 45694 | K2: 内部特别说明（不打印）
A3: 序号 | B3: 项目名称： | C3: 单位 | D3: 数量 | E3: 材料费 | G3: 人 工 费 | I3: 合计 | J3: 装饰内容及材质
E4: 主 | F4: 辅 | G4: 木(泥) | H4: 漆
A5: 一、土建拆除
A6: A、 | B6: 拆除非承重墙 | C6: m2 | D6: 1 | G6: 30 | I6: =D6*(E6+F6+G6+H6) -> 30 | J6: 1、拆除人工费。 2、不含门窗拆除。 3、不含构造柱拆除，构造柱需根据实际情况另计。 | K6: 大小门窗洞全扣，门窗由回收单位拆除。
A7: A、 | B7: 拆除半墙及修补 | C7: m2 | D7: 1 | F7: 40 | G7: 70 | I7: =D7*(E7+F7+G7+H7) -> 110 | J7: 1、拆除人工费。 2、不含门窗拆除。 3、不含构造柱拆除，构造柱需根据实际情况另计。 | K7: 大小门窗洞全扣，门窗由回收单位拆除。
A8: A、 | B8: 拆除构造柱 | C8: 根 | D8: 1 | G8: 150 | I8: =D8*(E8+F8+G8+H8) -> 150 | J8: 1、拆除人工费。
A9: A、 | B9: 拆除保温层 | C9: m2 | D9: 1 | G9: 20 | I9: =D9*(E9+F9+G9+H9) -> 20 | J9: 1、拆除人工费。 2、墙面拆除部分不重复计算保温层拆除。 | K9: 生活阳台及景观阳台有保温层
A10: A、 | B10: 拆除保温层后抹灰 | C10: m2 | D10: 1 | F10: 20 | G10: 25 | I10: =D10*(E10+F10+G10+H10) -> 45 | J10: 人工费+辅料
A11: A、 | B11: 拆除飘窗及修补（红砖） | C11: m | D11: 1 | F11: 100 | G11: 200 | I11: =D11*(E11+F11+G11+H11) -> 300 | J11: 1、拆除人工费。 2、不含构造柱拆除。 3、混凝土结构另计增加150/米。
A12: A、 | B12: 拆除飘窗及修补（混凝土） | C12: m | D12: 1 | F12: 100 | G12: 350 | I12: =D12*(E12+F12+G12+H12) -> 450 | J12: 1、拆除人工费。 2、不含构造柱拆除。
A13: A、 | B13: 拆除飘窗后墙地面防水 | C13: m2 | D13: 1 | F13: 25 | G13: 45 | I13: =D13*(E13+F13+G13+H13) -> 70 | J13: 1、法国“圣戈班伟伯”防水（刷二遍）；2、清洁并润湿原墙；3、向地面延伸100-200㎜，阴角饱满。
A14: A、 | B14: 原有墙\柱\梁倒圆角制作（R50mm以内） | C14: m | D14: 1 | E14: 20 | I14: =D14*(E14+F14+G14+H14) -> 20 | J14: 1、石匠踢打 2、R型阳角条漆工施工
A15: A、 | B15: 原有墙\柱\梁倒圆角制作（大于R50mm，小于R200mm） | C15: m | D15: 1 | E15: 20 | G15: 60 | I15: =D15*(E15+F15+G15+H15) -> 80 | J15: 1、石匠踢打 2、泥工搓沙
A16: A、 | B16: 原有墙\柱\梁倒圆角制作（大于R200mm） | C16: m | D16: 1 | E16: 40 | G16: 100 | I16: =D16*(E16+F16+G16+H16) -> 140 | J16: 1、红砖砌体 2、泥工搓沙
A17: 二、土建新建
A18: A、 | B18: 新砌100厚轻质砖墙 | C18: m2 | D18: 1 | E18: 70 | F18: 25 | G18: 50 | I18: =D18*(E18+F18+G18+H18) -> 145 | J18: 1、大面积加气混凝土砌体、局部红砖、水泥砂浆。使用于除地下室以外的区域；2、尺寸正确，表面平整，立面垂直。 | K18: 家装不允许使用轻质砖墙（加气砖），均计算为红砖。轻质砖仅起隔墙作用，红砖则有隔音隔热及承重。
A19: A、 | B19: 新砌200厚轻质砖墙 | C19: m2 | D19: 1 | E19: 160 | F19: 30 | G19: 40 | I19: =D19*(E19+F19+G19+H19) -> 230 | J19: 1、大面积加气混凝土砌体、局部红砖、水泥砂浆。使用于除地下室以外的区域；2、尺寸正确，表面平整，立面垂直。 | K19: 家装不允许使用轻质砖墙（加气砖），均计算为红砖。轻质砖仅起隔墙作用，红砖则有隔音隔热及承重。
A20: A、 | B20: 新砌砖墙（墙厚≤120mm） | C20: m2 | D20: 1 | E20: 90 | F20: 15 | G20: 60 | I20: =D20*(E20+F20+G20+H20) -> 165 | J20: 1、红砖、水泥砂浆。只使用于地下室；2、尺寸正确，表面平整，立面垂直。 | K20: 不加过梁的大小门窗洞全扣； 加过梁＜2㎡门窗洞不扣；加过梁≥2㎡门窗洞扣一半
A21: A、 | B21: 新砌砖墙（120＜墙厚≤240mm） | C21: m2 | D21: 1 | E21: 170 | F21: 20 | G21: 70 | I21: =D21*(E21+F21+G21+H21) -> 260 | J21: 1、红砖、水泥砂浆。只使用于地下室；2、尺寸正确，表面平整，立面垂直。 | K21: 不加过梁的大小门窗洞全扣； 加过梁＜2㎡门窗洞不扣；加过梁≥2㎡门窗洞扣一半
A22: A、 | B22: 单面抹灰、搓沙（按实计算） | C22: m2 | D22: 1 | E22: 20 | G22: 15 | I22: =D22*(E22+F22+G22+H22) -> 35 | J22: 1、水泥砂浆找平，综合价，厚度在30mm内不作调整；2、尺寸正确，表面平整，立面垂直。
A23: A、 | B23: 双面抹灰、搓沙（按实计算） | C23: m2 | D23: 1 | E23: 40 | G23: 30 | I23: =D23*(E23+F23+G23+H23) -> 70 | J23: 1、水泥砂浆找平，综合价，厚度在30mm内不作调整；2、尺寸正确，表面平整，立面垂直。
A24: A、 | B24: 开门洞 | C24: 个 | D24: 1 | G24: 150 | I24: =D24*(E24+F24+G24+H24) -> 150 | J24: 1、开门洞人工费。
A25: A、 | B25: 1000mm以下宽门洞过梁 | C25: 根 | D25: 1 | F25: 80 | G25: 110 | I25: =D25*(E25+F25+G25+H25) -> 190 | J25: 1、现浇过梁：钢筋+水泥+石子+砂+水；或预制过梁；2、梁端入墙100㎜以上。 2、大于1000mm计算为2根，以此类推。
A26: A、 | B26: 新做浴缸基层（不含贴面） | C26: 个 | D26: 1 | E26: 200 | F26: 50 | G26: 450 | I26: =D26*(E26+F26+G26+H26) -> 700 | J26: 1、红砖、水泥砂浆；2、尺寸正确，结构牢固，内侧抹灰收光。
A27: A、 | B27: 烟道保护 | C27: m2 | D27: 1 | E27: 100 | F27: 15 | G27: 100 | I27: =D27*(E27+F27+G27+H27) -> 215 | J27: 红砖、水泥砂浆；（按展开面积计算。） | K27: 必须单独计算，不能直接算进新建墙内。
A28: A、 | B28: 包落水管（按实际算） | C28: 根 | D28: 1 | E28: 60 | F28: 15 | G28: 150 | I28: =D28*(E28+F28+G28+H28) -> 225 | J28: 1、红砖、水泥砂浆。 2、含阻力片及隔音棉1公分厚度。 | K28: 必须单独计算，不能直接算进新建墙内。 一根管子算一根，双管算2根。
A29: A、 | B29: 电视墙加固 | C29: 项 | D29: 1 | E29: 100 | F29: 10 | G29: 80 | I29: =D29*(E29+F29+G29+H29) -> 190 | J29: 1、osb板或红砖+水泥、河砂；2、加固面积不得小于电视面积。
A30: A、 | B30: 入墙马桶 | C30: 个 | D30: 1 | F30: 100 | G30: 200 | I30: =D30*(E30+F30+G30+H30) -> 300 | J30: 暗藏水箱预埋（不含后期本体安装）。
A31: A、 | B31: 入墙预埋龙头 | C31: 个 | D31: 1 | F31: 50 | G31: 50 | I31: =D31*(E31+F31+G31+H31) -> 100 | J31: 开槽预埋件安装（不含后期本体安装）。
A32: A、 | B32: 原门洞修补 | C32: 个 | D32: 1 | E32: 50 | F32: 5 | G32: 80 | I32: =D32*(E32+F32+G32+H32) -> 135 | J32: 红砖、水泥砂浆或木龙骨（或木工板）+石膏板
A33: A、 | B33: 厨房和卫生间地面返水梁高度200mm（宽度≤120mm） | C33: m | D33: 1 | E33: 80 | F33: 20 | G33: 120 | I33: =D33*(E33+F33+G33+H33) -> 220 | J33: 1、现浇120mm梁：钢筋+水泥+石子+砂+水； | K33: 止水梁使用425水泥
A34: A、 | B34: 厨房和卫生间地面返水梁高度200mm（120≤宽度≤240mm） | C34: m | D34: 1 | E34: 100 | F34: 20 | G34: 160 | I34: =D34*(E34+F34+G34+H34) -> 280 | J34: 1、现浇240mm梁：钢筋+水泥+石子+砂+水； | K34: 止水梁使用425水泥
A35: A、 | B35: 厨房、卫生间、洗衣房、设备间、生活阳台线槽抹灰及防水处理 | C35: 个 | D35: 1 | E35: 100 | F35: 50 | G35: 250 | I35: =D35*(E35+F35+G35+H35) -> 400 | J35: 1、线槽内刷防水 | K35: 厨房，卫生间，洗衣房、设备间
A36: （一）、工程直接费 | C36: 元 | I36: =SUM(I4:I35) -> 5425
A37: （二）、工程综合管理费=（一）*12﹪ | C37: 元 | I37: =I36*0.12 -> 651 | J37: 1、签定施工合同进场后：10天内减少项目 减少管理费、10天后减少项目不减管理费；2、增加项目管理费相应增加
A38: （三）、工程总造价=（一）+（二） | C38: 元 | I38: =I36+I37 -> 6076
A39: 备注： 该报价不含小区物管收取的出渣费、电梯费、管理费、装修保证金等费用
A40: 设计师（签字） 设计部经理（签字） 客户（与合同名字一致）（签字）

Sheet 木基层报价（模板）
A1: 室内木基层工程报价清单
A2: 甲方（业主）姓名： 联系方式： 使用面积： 工程地点： 编制日期： | I2: =TODAY() -> 45694 | K2: 内部特别说明（不打印）
A3: 序号 | B3: 项目名称 | C3: 单位 | D3: 数量 | E3: 材料费 | G3: 人 工 费 | I3: 合计 | J3: 工艺做法及材料说明
E4: 主 | F4: 辅 | G4: 木(泥) | H4: 漆
A5: 一、木作基层工程
A6: A、 | B6: 墙面木作基层造型 | C6: m2 | D6: 1 | E6: 130 | F6: 10 | G6: 80 | I6: =D6*(E6+F6+G6+H6) -> 220 | J6: 1、12欧松板（加拿大进口兔宝宝）+龙骨基层 2、根据设计大样图及现场实际情况调整欧松板厚度。 | K6: 木饰面位置基层可以不计算，要求厂家施工或者做增项处理
A7: A、 | B7: 墙面石膏板封面(可耐福醛净单层） | C7: m2 | D7: 1 | E7: 40 | F7: 4.5 | G7: 37 | I7: =D7*(E7+F7+G7+H7) -> 81.5 | J7: 1、可耐福（醛净系列）家装专用石膏板(9.5mm厚)、春雨镀锌自攻钉固定,螺丝间距150mm；2、石膏板拼接留V型缝。3、饰面另计。4、边吊转角做“L”型处理
A8: A、 | B8: 墙面异形木作基层造型 | C8: m2 | D8: 1 | E8: =260-110 -> 150 | F8: 20 | G8: =240-80 -> 160 | I8: =D8*(E8+F8+G8+H8) -> 330 | J8: 1、12欧松板（加拿大进口兔宝宝）+龙骨基层 2、根据设计大样图及现场实际情况调整欧松板厚度。 | K8: 木饰面位置基层可以不计算，要求厂家施工或者做增项处理
A9: A、 | B9: 墙面异形石膏板封面(可耐福醛净单层） | C9: m2 | D9: 1 | E9: 60 | F9: 10 | G9: 50 | I9: =D9*(E9+F9+G9+H9) -> 120 | J9: 1、可耐福（醛净系列）家装专用石膏板(9.5mm厚)、春雨镀锌自攻钉固定,螺丝间距150mm；2、石膏板拼接留V型缝。3、饰面另计。4、边吊转角做“L”型处理
A10: A、 | B10: 暗踢脚墙体剔打，木基础，踢脚线安装 | C10: 米 | D10: 1 | E10: 35 | F10: 20 | G10: 40 | I10: =D10*(E10+F10+G10+H10) -> 95 | J10: 1、25-30mm踢脚线（含不锈钢或铝型材）。 2、30mm-50mm踢脚线需定制不锈钢不另外收费（含不锈钢）。 3、50mm以上踢脚线需定制不锈钢并另外收费20元/米（含不锈钢）。 4、定制颜色按20元/米增加费用。 | K10: 无踢脚线和内退踢脚线都需要计算,楼梯按步算，不按米算
A11: A、 | B11: 隐框门木基层 | C11: 米 | D11: 1 | E11: 65 | F11: 5 | G11: 45 | I11: =D11*(E11+F11+G11+H11) -> 115 | J11: 1、12欧松板（加拿大进口兔宝宝）+龙骨基层 2、根据设计大样图及现场实际情况调整欧松板厚度。 3、不含木饰面位置木基层。 | K11: 按门洞周长计算
A12: A、 | B12: 隐框门安装后收口处理 | C12: 米 | D12: 1 | E12: 65 | F12: 5 | G12: 35 | I12: =D12*(E12+F12+G12+H12) -> 105 | J12: 1、12欧松板（加拿大进口兔宝宝）+龙骨基层+石膏板封面 2、根据设计大样图及现场实际情况调整欧松板厚度。 3、不含木饰面位置木基层。 | K12: 按门洞周长计算
A13: A、 | B13: 极细边框木基层，定制不锈钢门套 | C13: 个 | D13: 1 | E13: 45 | F13: 10 | G13: 60 | I13: =D13*(E13+F13+G13+H13) -> 115 | J13: 750-900MM宽门（不含不锈钢）
A14: A、 | B14: 极细边框木基层，定制不锈钢门套 | C14: 个 | D14: 1 | E14: 500 | F14: 400 | G14: 500 | I14: =D14*(E14+F14+G14+H14) -> 1400 | J14: 750-900MM宽门（含不锈钢）
A15: A、 | B15: 极细边框木基层，定制不锈钢门套 | C15: 米 | D15: 1 | E15: 130 | F15: 30 | G15: 100 | I15: =D15*(E15+F15+G15+H15) -> 260 | J15: 门套宽度240mm以内（含不锈钢）
A16: A、 | B16: 平板门，含把手，普通合页和门吸 | C16: 扇 | D16: 1 | E16: 1800 | F16: 600 | G16: 300 | I16: =D16*(E16+F16+G16+H16) -> 2700 | J16: 2000-2400MM高
A17: A、 | B17: 中间铝蜂窝极窄边框门，含把手，普通合页和门吸 | C17: 扇 | D17: 1 | E17: 2000 | F17: 700 | G17: 700 | I17: =D17*(E17+F17+G17+H17) -> 3400 | J17: 2000-2400MM高
A18: A、 | B18: 不锈钢门套木基层 | C18: 米 | D18: 1 | E18: 65 | G18: 25 | I18: =D18*(E18+F18+G18+H18) -> 90 | J18: 1、12欧松板（加拿大进口兔宝宝）+龙骨基层 2、根据设计大样图及现场实际情况调整欧松板厚度。
A19: A、 | B19: 滑门轨道加固 | C19: m | D19: 1 | E19: 150 | G19: 200 | I19: =D19*(E19+F19+G19+H19) -> 350 | J19: 1、轨道钢架+木基层 | K19: 可列为非常规项目讲解
A20: A、 | B20: 钢架基层造型 | C20: ㎡ | D20: 1 | E20: 250 | G20: 200 | I20: =D20*(E20+F20+G20+H20) -> 450 | J20: 1、镀锌管，接头处涂刷防锈漆。 | K20: 可列为非常规项目讲解
A21: A、 | B21: 晾衣架加固 | C21: 项 | D21: 1 | E21: 200 | I21: =D21*(E21+F21+G21+H21) -> 200 | J21: 1、轨道钢架+木基层 | K21: 可列为非常规项目讲解
A22: （一）、工程直接费 | C22: 元 | I22: =SUM(I4:I17) -> 8941.5
A23: （二）、工程综合管理费=（一）*12﹪ | C23: 元 | I23: =I22*0.12 -> 1072.98 | J23: 1、签定施工合同进场后：10天内减少项目 减少管理费、10天后减少项目不减管理费；2、增加项目管理费相应增加
A24: （三）、工程总造价=（一）+（二） | C24: 元 | I24: =I22+I23 -> 10014.48
A25: 备注： 该报价不含小区物管收取的出渣费、电梯费、管理费、装修保证金等费用
A26: 设计师（签字） 设计部经理（签字） 客户（与合同名字一致）（签字）

Sheet 远征费（内部）
A1: 远征费价格表
A3: 造价 城市 | B3: 7W以内（含7万） | C3: 7-10.5W以内（含10.5万） | D3: 10.5-14W以内（含14万） | E3: 14-17.5W以内（含17.5万） | F3: 17.5-21W以内（含21万） | G3: 21-24.5W以内（含24.5万） | H3: 24.5-28W以内（含28万） | I3: 28W以上
A5: 涪陵 | B5: 7750 | C5: 8850 | D5: 10000 | E5: 12150 | F5: 15100 | G5: 17050 | H5: 22100 | I5: 24450
A6: 丰都 | B6: 8800 | C6: 10000 | D6: 11350 | E6: 13800 | F6: 16900 | G6: 19100 | H6: 24300 | I6: 26950
A7: 石柱 | B7: 11100 | C7: 12500 | D7: 14000 | E7: 17100 | F7: 20500 | G7: 23300 | H7: 28800 | I7: 32050
A8: 利川 | B8: 14900 | C8: 16600 | D8: 18500 | E8: 22650 | F8: 26500 | G8: 30300 | H8: 36200 | I8: 40550
A9: 长寿 | B9: 4250 | C9: 5100 | D9: 6000 | E9: 7250 | F9: 9650 | G9: 11000 | H9: 15350 | I9: 17100
A10: 垫江 | B10: 9200 | C10: 10550 | D10: 12000 | E10: 14500 | F10: 17800 | G10: 20000 | H10: 25400 | I10: 28100
A11: 忠县 | B11: 12050 | C11: 13700 | D11: 15500 | E11: 18800 | F11: 22500 | G11: 25400 | H11: 31200 | I11: 34650
A12: 梁平 | B12: 10800 | C12: 12300 | D12: 13850 | E12: 16800 | F12: 20300 | G12: 22950 | H12: 28500 | I12: 31650
A13: 万州 | B13: 13500 | C13: 15000 | D13: 16500 | E13: 20300 | F13: 23950 | G13: 27150 | H13: 33050 | I13: 36700
A14: 开县 | B14: 18450 | C14: 20800 | D14: 23400 | E14: 28300 | F14: 33350 | G14: 37400 | H14: 44600 | I14: 49300
A15: 城口 | B15: 21800 | C15: 24500 | D15: 27400 | E15: 33250 | F15: 38750 | G15: 43650 | H15: 51300 | I15: 56900
A16: 云阳 | B16: 19700 | C16: 22300 | D16: 25200 | E16: 30350 | F16: 35750 | G16: 40000 | H16: 47600 | I16: 52500
... A44: 上邦高尔夫 | B44: 3000 | C44: 4000 | D44: 5000 | E44: 6000 | F44: 7000 | G44: 8000 | H44: 9000 | I44: 10000
A45: 说明：
A46: １） 远征费收取对象：凡重庆主城区以外的区域，
A47: ２） 以上城市附近的区域（如镇、村），在原价格的基础上，根据实际情况适当上调
A48: ３） 远征费组成方式：
A49: 1, 材料车运费 (至少3车)
A50: 2, 工人往返车费 (至少12人次来回)
A51: 3, 管理人员往返车费 ( 至少24人次来回)
A52: 4, 工人路途中误工费 (250/天)
A53: 5, 工人住宿费 (房租费) (至少550/月)
A54: 6, 同一小区内，且在一周内相继进场的两个工程，其远征费同时下浮20%（北碚紫云台除外）
A55: 7, 同一小区内，且在两周内相继进场的三个工程，其远征费同时下浮30%（北碚紫云台除外）

Sheet 基装材料表（内部）
A1: 昱辰设计施工材料目录表
A2: 注：工地实际用材以预算报价表中材料明细为准！
A3: 类别 | B3: 品 牌 | C3: 产地 | D3: 材料名称 | E3: 市场参考规格
A4: 欧松板 | B4: 克诺斯邦 | C4: 俄罗斯（原装进口） | D4: OSB板 | E4: 2400*1220*9mm
E5: 2400*1220*12mm
E6: 2400*1220*15mm
B7: 兔宝宝（标配） | C7: 加拿大（原装进口） | D7: OSB板 | E7: 2400*1220*9mm
E8: 2400*1220*12mm
E9: 2400*1220*15mm
A10: 多层板 | B10: 千年舟 | C10: 浙江 | D10: 木工板 | E10: 2440*1220*15mm
C11: 浙江 | D11: 十五厘
C12: 浙江 | D12: 九厘 | E12: 1200*2400*9mm
C13: 浙江 | D13: 五厘 | E13: 1200*2400*5mm
A14: 石膏板 | B14: 可耐福（德国品牌） | C14: 安徽 | D14: 醛净系列 | E14: 2400*1220*9.5mm
B15: 可耐福耐潮石膏板（德国品牌） | D15: 耐潮板 | E15: 2400*1220*9.5mm
A16: 轻钢龙骨 | B16: 肯努森 | C16: 重庆 | D16: 吊顶卡式主龙骨（50系列） | E16: 20*37*0.8*3000
B17: 肯努森 | D17: 吊顶收边龙骨（50系列） | E17: 20*20*30*0.5*3000
B18: 肯努森 | D18: 吊顶卡式副龙骨（50系列） | E18: 50*19*0.5*3000
B19: 肯努森 | D19: F型边龙骨（50系列） | E19: 30*50*50*0.5*3000
B20: 肯努森 | D20: L型边龙骨（50系列） | E20: 30*30*0.5*3000
B21: 肯努森 | D21: 吊顶卡式主龙骨（60系列） | E21: 25*40*0.8*3000
B22: 肯努森 | D22: 吊顶收边龙骨（60系列） | E22: 20*30*30*0.5*3000
B23: 肯努森 | D23: 吊顶卡式副龙骨（60系列） | E23: 60*27*0.6*3000
A24: 轻钢龙骨（黄金龙骨） | B24: 圣戈班杰科（法国品牌） | C24: 重庆 | D24: 吊顶卡式主龙骨（50系列） | E24: 20*37*0.8*2800
B25: 圣戈班杰科（法国品牌） | D25: 吊顶收边龙骨（50系列） | E25: 20*20*34*0.4*2800
B26: 圣戈班杰科（法国品牌） | D26: 吊顶卡式副龙骨（50系列） | E26: 50*19*0.45*2800
B27: 圣戈班杰科（法国品牌） | D27: 吊顶卡式主龙骨（60系列） | E27: 26*37*1.0*2800
B28: 圣戈班杰科（法国品牌） | D28: 吊顶收边龙骨（60系列） | E28: 27*27*28*0.5*2800
B29: 圣戈班杰科（法国品牌） | D29: 吊顶卡式副龙骨（60系列） | E29: 60*27*0.5*2800
A30: 腻子 | B30: 西卡（瑞士品牌） | C30: 成都 | D30: 粉刷石膏 | E30: 20kg
D31: 面层找平腻子
D32: 嵌缝石膏
A33: 腻子 | B33: 圣戈班杰科（法国品牌） | C33: 重庆 | D33: 底层找平 | E33: 20kg
B34: 圣戈班杰科（法国品牌） | D34: 满批腻子
B35: 圣戈班杰科（法国品牌） | D35: 高强耐水腻子
A36: 墙地固 | B36: 西卡（瑞士品牌） | C36: 成都 | D36: 环保墙面封固剂 | E36: 9kg
D37: 环保墙面封闭地固 | E37: 9kg
A38: 墙地固 | B38: 圣戈班杰科（法国品牌） | C38: 重庆 | D38: 墙面加固界面剂(黄色） | E38: 18kg
B39: 圣戈班杰科（法国品牌） | D39: 墙面加固界面剂(白色) | E39: 18kg
A40: 防水 | B40: 圣戈班伟伯（法国品牌） | C40: 上海 | D40: 伟伯(金装全效通用型蓝色双组份K11) | E40: 20kg
...

Sheet 基装材料厂家资料介绍（内部）
A1: 室内基础装饰工程材料明细表
A2: 序号 | B2: 材料名称 | C2: 品 牌 | D2: 材料说明 | E2: 规格等级 | F2: 材料图片 | G2: 使用区域 | H2: 备注
A3: 1 | B3: 轻钢龙骨 | C3: 肯努森 | D3: 杜伊斯堡是德国的钢铁重镇，当穿梭在被百年时光洗礼过后的城市，不时会觉得钢铁给这座城市带来的不朽；然而低头俯视锈迹斑驳的锈色时感到的是悲凉… 公司总裁站在蒂森克虏伯钢铁工厂当机做出决定，针对公司的高端轻钢龙骨做到防锈处理，抛弃传统的镀锌防锈，做到在传统镀锌的表面再增加一层防锈涂层； 我们会道盾“诚信，"品质””专注”“创新〞的发展理念，来引领着行业的发展，希望通过我们不断的努力创造出永不腐朽的钢铁森林。 这就是肯努森的由来。 肯努森轻钢龙骨具有耐腐蚀、设计多元化、隔热降噪、施工方便等优秀特点，包括2D吊顶龙骨、ZX造型龙骨两种系列龙骨，为客户带来更多的家装选择。 zD吊顶龙骨 zX造型龙骨 全套设备采用高速自动生产线设备，承载龙骨采用小卡口塑型，采用镀锌＋涂层钢 带为 原料，超强的耐腐蚀性能，提供高端定制生产 采用半自动生产设备，采用连縷冷轧热镇锌钢带为原料和涂层钢带，提供高端定制 生产：Zx龙骨包含：造型龙骨、下龙骨、L龙骨、CH龙骨、E型龙骨 | E3: 吊顶卡式主龙骨（50）20*37*0.8*3000 吊顶收边龙骨（50） 20*20*30*0.5*3000 吊顶卡式副龙骨（50） 50*19*0.5*3000 F型边龙骨（50） 30*50*50*0.5*3000 L型边龙骨（50） 30*30*0.5*3000 | G3: 天棚吊顶
A4: 2 | B4: 石膏板 | C4: 可耐福Knauf | D4: 1.可耐福创建于1932年，总部位于德国依普霍芬，是世界领先的建筑系统与绿色建材的制造商。 目前，可耐福全球销售网络遍布86个国家和地区，拥有超过12个子品牌、220个生产基地、逾30,000名员工。在中国仍保持着以石膏产品为核心业务，多种建筑材料及配套系统共同发展的格局，为建筑提供涉及建筑外墙、内墙、吊顶、地面等全系统解决方案。 2.具有卓越的甲醛分解作用 3.对TVOC和氨气也具有一定的分解作用 4.减少空气中的异味和有害物质 5.可耐福醛净标准纸面石膏板为粉红色面纸，表面可以满批处理或直接涂刷底漆、粘贴墙纸墙布作为终饰表面均可获得理想的效果。添加了更多的无碱纤维，提高板的强度，完全符合GB/T 9775-2008标准。采用欧洲独特配方，可有效分解甲醛，去除空气中的甲醛含量 | E4: 可耐福Cleaneo C 醛净石膏板 1200mm×2400mm×9.5mm | G4: 天棚吊顶 | H4: 特点及使用部位： ■ 适用于一般需求的场所 ■ 可用于隔墙、吊顶、贴面墙等轻质墙体系统 ■ 可有效分解甲醛，去除空气中的甲醛含量
A5: 3 | B5: 耐潮纸面石膏板 | C5: 可耐福Knauf | D5: 1.可耐福创建于1932年，总部位于德国依普霍芬，是世界领先的建筑系统与绿色建材的制造商。 目前，可耐福全球销售网络遍布86个国家和地区，拥有超过12个子品牌、220个生产基地、逾30,000名员工。在中国仍保持着以石膏产品为核心业务，多种建筑材料及配套系统共同发展的格局，为建筑提供涉及建筑外墙、内墙、吊顶、地面等全系统解决方案。 2.可耐福耐潮板是专为普通潮湿环境而开发生产的防潮类轻质板材 耐水性能介于标准板和耐水板间的欧标H3类纸面石膏板 板芯内加入的高效有机疏水剂，经过有机防水材料特殊处理的护面纸，较好地改善了纸面石膏板的抗水性和憎水效果 | E5: 耐潮纸面石膏板 1200mm×2400mm×9.5mm | G5: 天棚吊顶 | H5: 特点及使用部位： ■ 适用于卫生间、厨房、地下室、潮湿厂房等隔墙和吊顶 ■ 偶尔临水或短时间浸泡场所 ■ 临时暴露墙或吊顶应用 外墙系统的内侧板材 井道墙内侧（井道一侧）板
A6: 4 | B6: OSB板 | C6: 克诺斯邦（俄罗斯） | D6: 克诺斯邦品牌故事：1897年，诞生过音乐神童莫扎特的奥地利古城Salzburg城郊的Lungoetz小镇上，年轻的卡恩先生继承了父亲传下来的木工手艺，并凭着自己天赋的艺术悟性不断改进工艺，使原本笨拙的木器平添了几分如音乐般的韵律与华丽。卡恩的名声很快在当地传开。1897年，Salzburg大公为幼子举办婚礼，特向卡恩定制婚后所需的木制品，并让他负责日后城堡中所有木制品的供应。为此，卡恩决定创立自己的木材加工工厂。Krono（柯诺）集团由此成立！ 产品介绍：OSB Superfinish(OSB标准板)是目前的常规板。OSB Superfinish 是当今最先进的定向刨花板。为满足当下生态环境对有机材料的需求, OSB Superfinish应运而生。由于选择了合适的木片和无醛胶，OSB Superfinish不仅只限于满足高标准的环保建筑要求。 使用的胶是无醛胶, 所以甲醛含量仅限于木材本身的含量（<0.03ppm)。 规格标准：欧标 EN 300-OSB4， EN 13501-1: D-s1,d0级 甲醛含量等级：E1(EN 120) 产品特性：使用容易固定的常规紧固件(螺丝、钉子、订书钉) - 易加工 - 性价比高 - 卓越的加工性能 - 极其耐久和抵抗外部损坏 - 良好的承载能力 - 材料高效利用 - 高稳定性 - 增强耐潮性能 | E6: E0级 1200mm×2400mm×5-15mm | G6: 天棚造型
A7: 5 | B7: OSB板 | C7: 兔宝宝 加拿大（原装进口） | D7: 1、2013年4月17日双方正式开始在木材加工技术领域的合作。以加拿大原产地优质颤杨为原料，将原木进行刨片，通过专用设备经干燥、施胶、定向铺装热压成型等工艺制成的一种新型工程板材。 产品特性： ①异氰酸脂木材专用胶粘剂不含甲醛。 ②高温、压力热压过程中原材料内部先期释放甲醛。 ③精选生长周期80-120年的加拿大原生颤杨；刨切成4.5CM厚，四层原木片纵横交错铺装，表层和芯层规律配比，三层定向铺排；表里如一。 ④精准数据操作，采用德国格林策巴赫 12 英尺宽连续压机生产线精制而成，板材通体密闭，均匀统一，无外观缺陷，无尺寸偏差；纹理自然美观，满足设计师个性需求。 | E7: ENF级 1220mm×2440mm×9-15mm | G7: 天棚造型、基层造型
A8: 6 | B8: 丝杆 | C8: 浙江产 | D8: 1.丝杆镀锌工艺，可以有效的防止生锈 2.全牙丝杆，可以自由的调整螺母的位置，可以自由的调整被吊物体的高度 | E8: 镀锌全牙丝杆Φ8 | G8: 天棚造型
A9: 7 | B9: 石膏板螺丝 | C9: 春雨 | D9: 1.钢制经表面镀锌钝化，可以有效的防止生锈 2.安全牢固，不断折、不变形 3.连接方便、快捷，操作简单 | E9: 3.5*25 3.5*35 | G9: 天棚吊顶
A10: 8 | B10: 乳胶漆 | C10: PPG大师漆（美国） | D10: 1.PPG公司始建于1883年, 总部位于美国匹兹堡市，是全球性油漆、涂料、化学品、光学产品、特种材料的供应商。PPG目前在全球70多个国家设有140多个生产基地及附属机构。PPG是福布斯世界500强，财富杂志美国200强， 2019年公司全球销售额达到151.4亿美金。 2.大师芬美内墙底漆具有优良的耐碱性、更高遮盖力。 | E10: 白色：18L | G10: 吊顶墙面 | H10: 1.避免在雨天和相对湿度大于80%条件下施工。施工适宜环境温度为5-35℃ 涂料使用之前充分搅拌均匀 2.每次涂刷前需保证基层或前道漆膜完全干透 3.避免与硝基、聚酯类等高挥发性漆同时施工，以防止乳胶漆墙面被薰黄
A11: 9 | B11: 墙底漆 | C11: PPG大师漆（美国） | D11: 1.PPG公司始建于1883年, 总部位于美国匹兹堡市，是全球性油漆、涂料、化学品、光学产品、特种材料的供应商。PPG目前在全球70多个国家设有140多个生产基地及附属机构。PPG是福布斯世界500强，财富杂志美国200强， 2019年公司全球销售额达到151.4亿美金。 2.大师芬美内墙底漆具有优良的耐碱性、更高遮盖力。 | E11: 白色：18L | G11: 吊顶墙面 | H11: 1.避免在雨天和相对湿度大于80%条件下施工。施工适宜环境温度为5-35℃ 涂料使用之前充分搅拌均匀 2.每次涂刷前需保证基层或前道漆膜完全干透 3.避免与硝基、聚酯类等高挥发性漆同时施工，以防止乳胶漆墙面被薰黄
A12: 10 | B12: 防水涂料 | C12: 圣戈班伟伯（法国） | D12: 1.1900年 Weber et Broutin于20世纪初在法国成立。George Weber及Jean-Baptiste Broutin先生在巴黎建立了生产石膏及石灰基的外墙饰面砂浆的工厂。世界500百强，全球工艺百强，在世界各地拥有工厂。2016年 圣戈班在中国武汉设立生产基地。 2.良好的抗渗性能，高粘结强度 3.环保无公害 | E12: 20KG/桶 | G12: 厨房，卫生间，阳台防水
A13: 11 | B13: 底层找平腻子 | C13: 圣戈班杰科（法国品牌） | D13: 1、一道做厚省工省时，一次找平3~10mm 2、适用于砖、混凝土、砌块、水泥墙面以及翻新墙面不平整处找平 3、墙面旧腻子必须铲除到见基层，后用加固剂处理，混凝土表面需采用加固剂处理 4、施工温度:5~35℃，相对湿度40%~85%，基层表面清洁干燥，施工容器没有残渣 5、与水调和即可，水与粉比例约为1:2，高温、低湿季节需要多加水，调和完后请在60分钟内用完 6、参考用量:1mm厚1平方米用量约为1.25kg | E13: 20KG/袋 | G13: 墙面
A14: 12 | B14: 满批腻子 | C14: 圣戈班杰科（法国品牌） | D14: 1、易批刮，易打磨，省工省力 2、适用于石膏板表面的精细找平以及与建筑物内墙和顶面的精细找平,与圣戈班杰科底层找平配套使用 3、每道批抹厚度为0.5mm~1.5mm，均匀平整。腻子层完全干燥后可进行打磨和涂料施工 4、施工温度:5~35℃，相对湿度40%~85% 5、与水调和即可，水与粉比例约为1:2.5，高温、低湿季节需要多加水 6、参考用量:20kg本产品理论上可用于18~20平方米面层满批(1mm厚) 7、不能与其他产品混用 | E14: 20KG/袋 | G14: 吊顶、墙面
A15: 13 | B15: 高强防水平腻子 | C15: 圣戈班杰科（法国品牌） | D15: 1、易批刮，易打磨，省工省力 2、适用于室内墙面和顶面涂料涂刷前的精细找平，尤其适用于潮湿环境或粘结强度要求较高的墙面和顶面的精细找平 3、每道批抹厚度为0.5mm~1.5mm，均匀平整。腻子层完全干燥后可进行打磨和饰面施工 4、施工温度:5~35℃，相对湿度40%~85% 5、与水调和即可，水与粉比例约为1:2.5，高温、低湿季节需要多加水，调和完后请在240分钟内用完 6、参考用量:基层平整的情况下约为1.2~1.8kg/m 7、不能与其他产品混用 | E15: 20KG/袋 | G15: 吊顶、墙面
A16: 14 | B16: 嵌缝石膏 | C16: 西卡（瑞士） | D16: 1、西卡中国总部位于苏州，提供从屋面到地面的完整的建筑材料产品，包括先进的混凝土外加剂、屋面和防水卷材、地坪材料、密封胶、砂浆和灌浆。西卡工业解决方案使车辆重量更轻，从而降低油耗，提高生产效率，并增强安全性和舒适性。凭借强大的技术支持，西卡为客户提供完整的解决方案。西卡在持续快速发展的同时也致力于人才的全方位培养和储备，完整的人才发展体系，以培训生项目为基础，通过领导力，销售能力以及技术开发能力三支柱，层层递进，在保障员工自身发展的同时为公司的飞速发展提供源源不断的专业人才。 西卡作为一个有着超过100年历史的成功的特殊化学品制造商，以“更多价值，更少影响”为核心的可持续发展战略是业务运营和企业文化的核心要素。勇于创新，敢于坚持，乐于合作是西卡人对客户，对社会不变的承诺！ 应用范围：_x005f_x005f_x005f_x005f_x005f_x005f_x005f_x005f_x005f_x005f_x005f_x005f_x005f_x005f_x005f_x005f_x005f_x005f_x005f_x005f_x005f_x005f_x005f_x005f_x005f_x005f_x005f_x005f_x005f_x005f_x005f_x005f_x005f_x005f_x005f_x005f_x005f_x005f_x005f_x005f_x005f_x005f_x005f_x005f_x005f_x005f_x005f_x005f_x005f_x005f_x005f_x005f_x005f_x005f_x005f_x005f_x005f_x005f_x005f_x005f_x005f_x005f_x000b_石膏板接缝处理、墙体裂缝处理、阴阳角处理以及局部修补找平 功能特点： 绿色环保 收缩小，不开裂 粘结强度高_x000b__x000b_ | E16: 20KG/袋 | G16: 墙面
A17: 15 | B17: 粉刷石膏 | C17: 西卡（瑞士） | D17: 1、西卡中国总部位于苏州，提供从屋面到地面的完整的建筑材料产品，包括先进的混凝土外加剂、屋面和防水卷材、地坪材料、密封胶、砂浆和灌浆。西卡工业解决方案使车辆重量更轻，从而降低油耗，提高生产效率，并增强安全性和舒适性。凭借强大的技术支持，西卡为客户提供完整的解决方案。西卡在持续快速发展的同时也致力于人才的全方位培养和储备，完整的人才发展体系，以培训生项目为基础，通过领导力，销售能力以及技术开发能力三支柱，层层递进，在保障员工自身发展的同时为公司的飞速发展提供源源不断的专业人才。 西卡作为一个有着超过100年历史的成功的特殊化学品制造商，以“更多价值，更少影响”为核心的可持续发展战略是业务运营和企业文化的核心要素。勇于创新，敢于坚持，乐于合作是西卡人对客户，对社会不变的承诺！ 应用范围：_x005f_x005f_x005f_x005f_x005f_x005f_x005f_x005f_x005f_x005f_x005f_x005f_x005f_x005f_x005f_x005f_x005f_x005f_x005f_x005f_x005f_x005f_x005f_x005f_x005f_x005f_x005f_x005f_x005f_x005f_x005f_x005f_x005f_x005f_x005f_x005f_x005f_x005f_x005f_x005f_x005f_x005f_x005f_x005f_x005f_x005f_x005f_x005f_x005f_x005f_x005f_x005f_x005f_x005f_x005f_x005f_x005f_x005f_x005f_x005f_x005f_x005f_x005f_x000b_室内非潮湿区域的墙面及顶棚的找平处理，有效缩短施工周期 功能特点： 快干高效 坚固耐久 粘结力强_x000b__x000b_ | E17: 20KG/袋 | G17: 墙面找平
A18: 16 | B18: 面层找平腻子 | C18: 西卡（瑞士） | D18: 1、西卡中国总部位于苏州，提供从屋面到地面的完整的建筑材料产品，包括先进的混凝土外加剂、屋面和防水卷材、地坪材料、密封胶、砂浆和灌浆。西卡工业解决方案使车辆重量更轻，从而降低油耗，提高生产效率，并增强安全性和舒适性。凭借强大的技术支持，西卡为客户提供完整的解决方案。西卡在持续快速发展的同时也致力于人才的全方位培养和储备，完整的人才发展体系，以培训生项目为基础，通过领导力，销售能力以及技术开发能力三支柱，层层递进，在保障员工自身发展的同时为公司的飞速发展提供源源不断的专业人才。 西卡作为一个有着超过100年历史的成功的特殊化学品制造商，以“更多价值，更少影响”为核心的可持续发展战略是业务运营和企业文化的核心要素。勇于创新，敢于坚持，乐于合作是西卡人对客户，对社会不变的承诺！ 应用范围：_x005f_x005f_x005f_x005f_x005f_x005f_x005f_x005f_x005f_x005f_x005f_x005f_x005f_x005f_x005f_x005f_x005f_x005f_x005f_x005f_x005f_x005f_x005f_x005f_x005f_x005f_x005f_x005f_x005f_x005f_x005f_x005f_x005f_x005f_x005f_x005f_x005f_x005f_x005f_x005f_x005f_x005f_x005f_x005f_x005f_x005f_x005f_x005f_x005f_x005f_x005f_x005f_x005f_x005f_x005f_x005f_x005f_x005f_x005f_x005f_x005f_x005f_x005f_x000b_室内非潮湿区域的墙面及顶棚的找平处理，有效缩短施工周期 功能特点：快干高效 坚固耐久 粘结力强_x000b__x000b_ | E18: 20KG/袋 | G18: 吊顶墙面
A19: 17 | B19: 电线 | C19: 鸽牌 | D19: 1.重庆鸽牌电线电缆有限公司，60 多年来专注于电线电缆、铜型材、高压电瓷、塑胶管业的研发，致力于为国际国内航天航空、轨道交通、发电机组、输配电工程配套及家装系列提供安全、节能、环保的产品设计和生产制造。公司现为中国西部最大的家装电线、特种电缆、电工用铜型材产品加工制造基地。 2.目前，公司已占据重庆家装电线市场份额的绝对领导地位，产销量位居全国三甲，产品畅销西南地区及全国，并逐步向亚、欧、美等诸多国家和地区延伸，为三峡电站、西昌卫星发射中心、重庆江北国际机场、重庆国际会展中心、重庆轨道交通等国家及重庆市重点工程采用。 3.采用带测偏仪的三层共挤交联挤出生产线进行生产，内处屏蔽料和绝缘料选用合格供应商提供的、经检验合格，并存放于交货间的原材料。生产过程控制按相应的工艺规程进行。 | E19: 型号：60227 IEC 01(BV) 规格：1*1.5 1*2.5 1*4 1*6 1*1.5(B) 型号：BVR 规格：1*2.5 1*4 1*6
A20: 18 | B20: 电线 | C20: 普睿司曼（意大利） | D20: 1.意大利普睿司曼集团始于1879年，是全球通信和能源电缆行业的领导者。在51个国家拥有112家工厂和26个研发中心，年销售额大约110亿欧元。普睿司曼集团旗下拥有Prysmian和Draka两大世界知名品牌,总部位于意大利米兰，是米兰交易所上市企业。 2.采用巴西进口的绝缘材料，来自植物提取物，代表了当今最领先的科技，是目前行业内最安全的电线； 3. 环保：玉米、甘蔗和甜菜的提取物，不对环境造成再次污染； 4.通过欧盟ROHS环保指令； 5. 安全：无烟、无卤，不释放有害气体，无任何重金属和有害物质； 6. C 级阻燃:工作温度提高20%（85℃），短路温度250℃； 7. 双层共挤：其中内层为本色料，绝缘效果更好，减少颜料分子对铜导体的侵蚀及介电损耗，通常是高端产品才会使用的工艺。 | E20: 线芯结构； 1.5平方30*0.25mm 2.5平方50*0.25mm 4平方56*0.3mm 6平方84*0.3mm
A21: 19 | B21: 排水管 | C21: 索邦（德国） | D21: 1.索邦品牌1924年诞生于德国的慕尼黑，是一家专业生产工业管道和家用开关的大型跨国集团，2008年开始进入中国市场。2015年，索邦管道凭借过硬的产品质量，荣获了国家质量总局颁发的全国“质量标杆企业”荣誉称号，集团还先后获得中国管业十大品牌、全国质量与服务诚信优秀企业等各种荣誉50余项，拥有各项专利技术1百多个。 2.生产设备采用德国挤出生产线，主辅材料采用进口高品质原料。 3.每一根U-PVC管都具有内壁光滑，摩阻系数低的特点。在使用过程中，排水流量大，同时污垢不易附着。 4.水管具有优越的物理性能，产品表面经过索邦独有防晒工艺处理，大大加强了产品的曝光性。即便是长期在阳光下直射使用，也不影响产品品质。产品的抗震抗压性能好，十分坚固耐用。 | E21: PVC下水管 | G21: 下水道
A22: 20 | B22: 给水管 | C22: 深亘（原装进口德国） | D22: Karl- Schöngen塑料管道系统是一家生产和销售用于电缆保护和露天建筑的下水管道以及PPR给水管道系统及其相关配件的跨国公司。 公司的两大生产基地位于下萨克森州和萨尔茨吉特，目前拥有120名技术人员，为全球的用户在能源供应、电信、水处理及建筑领域提供方案。 自1956年由Karl-Schöngen先生成立的以来,公司已经经历了三个阶段的发展与变化。德国深亘的PP-R管道特点Die Produkteigenschaften der PPR Rohre 1、管道原装进口产品，德国工艺，产品品质高端。 2、管道采用食品级北欧化工原料，绿色卫生。安全可靠，符合德国标准。 3、管道热稳定性、抗冲击性、环境兼容性高。 4、管道耐腐蚀、耐磨损、耐高温耐压性能卓越，维卡耐热温度131.3C 5、管道运行性能稳定，使用寿命长，使用50年以上， 6、管道内壁光滑、不结垢、流体阻力小。 7、管道热熔时，无色无味，不产生刺激性气味。 8、管道采用热熔连接方式，不渗漏，安全可靠。 9、管道铜管件采用欧洲标准环保铜，无镍铬。 10、管道壁厚加厚处理，承压性能强。 | E22: PP-R给水管 | G22: 给水管
